Workbook

Sheet Start_page

Sheet Data1
A1: =$O$1/100 -> 0.03 | B1: {=1-COS((_xlfn.SEQUENCE(500,1,0,1)*PI())/(2*(500-1)))} -> 0 | C1: =IF($A$1=0, 0, IF(B1<=$A$2, ($A$1/$A$2^2)*(2*$A$2*B1-B1^2), ($A$1/(1-$A$2)^2)*((1-2*$A$2)+2*$A$2*B1-B1^2))) -> 0 | D1: =5*$A$3*(0.2969*SQRT(B1)-0.126*B1-0.3516*B1^2+0.2843*B1^3-0.1015*B1^4) -> 0 | E1: =IF($A$1=0, 0, IF(B1<=$A$2, ($A$1/$A$2^2) *(2*$A$2-2*B1), ($A$1/(1-$A$2)^2)*(2*$A$2-2*B1))) -> 0.15 | F1: =IF($A$1=0, 0, ATAN(E1)) -> 0.14888995 | G1: =B1-D1*SIN(F1) -> 0 | H1: =C1+D1*COS(F1) -> 0 | I1: =B1+D1*SIN(F1) -> 0 | J1: =C1-D1*COS(F1) -> 0 | M1: =IF($Q$1, C1, -0.2) -> -0.2 | N1: 3 | O1: =IF($P$1=1, 0, $N$1) -> 3 | P1: 2 | Q1: FALSE | R1: =ATAN(E1) -> 0.14888995 | S1: {=_xlfn.SEQUENCE(50, 1, 0, (2*PI())/(50-1))} -> 0 | T1: =$R$2*(COS($R$1)+COS(S1)) -> 0.096647335 | U1: =IF($Q$2, $R$2*(SIN($R$1)+SIN(S1)), -0.2) -> -0.2
A2: =$O$2/10 -> 0.4 | B2: 4.9545967e-06 | C2: =IF($A$1=0, 0, IF(B2<=$A$2, ($A$1/$A$2^2)*(2*$A$2*B2-B2^2), ($A$1/(1-$A$2)^2)*((1-2*$A$2)+2*$A$2*B2-B2^2))) -> 7.431849e-07 | D2: =5*$A$3*(0.2969*SQRT(B2)-0.126*B2-0.3516*B2^2+0.2843*B2^3-0.1015*B2^4) -> 0.0006932553 | E2: =IF($A$1=0, 0, IF(B2<=$A$2, ($A$1/$A$2^2) *(2*$A$2-2*B2), ($A$1/(1-$A$2)^2)*(2*$A$2-2*B2))) -> 0.14999814 | F2: =IF($A$1=0, 0, ATAN(E2)) -> 0.14888813 | G2: =B2-D2*SIN(F2) -> -9.7881963e-05 | H2: =C2+D2*COS(F2) -> 0.00068632874 | I2: =B2+D2*SIN(F2) -> 0.00010779116 | J2: =C2-D2*COS(F2) -> -0.00068484237 | M2: =IF($Q$1, C2, -0.2) -> -0.2 | N2: 4 | O2: =IF($P$1=1, 0, $N$2) -> 4 | Q2: FALSE | R2: =(0.2969^2/2)*(A3/0.2)^2 -> 0.048592473 | S2: 0.12822827 | T2: =$R$2*(COS($R$1)+COS(S2)) -> 0.096248392 | U2: =IF($Q$2, $R$2*(SIN($R$1)+SIN(S2)), -0.2) -> -0.2
A3: =O3/100 -> 0.21 | B3: 1.9818338e-05 | C3: =IF($A$1=0, 0, IF(B3<=$A$2, ($A$1/$A$2^2)*(2*$A$2*B3-B3^2), ($A$1/(1-$A$2)^2)*((1-2*$A$2)+2*$A$2*B3-B3^2))) -> 2.972677e-06 | D3: =5*$A$3*(0.2969*SQRT(B3)-0.126*B3-0.3516*B3^2+0.2843*B3^3-0.1015*B3^4) -> 0.0013851978 | E3: =IF($A$1=0, 0, IF(B3<=$A$2, ($A$1/$A$2^2) *(2*$A$2-2*B3), ($A$1/(1-$A$2)^2)*(2*$A$2-2*B3))) -> 0.14999257 | F3: =IF($A$1=0, 0, ATAN(E3)) -> 0.14888268 | G3: =B3-D3*SIN(F3) -> -0.00018565257 | H3: =C3+D3*COS(F3) -> 0.0013728466 | I3: =B3+D3*SIN(F3) -> 0.00022528925 | J3: =C3-D3*COS(F3) -> -0.0013669013 | M3: =IF($Q$1, C3, -0.2) -> -0.2 | O3: 21 | S3: 0.25645654 | T3: =$R$2*(COS($R$1)+COS(S3)) -> 0.095058112 | U3: =IF($Q$2, $R$2*(SIN($R$1)+SIN(S3)), -0.2) -> -0.2
B4: 4.4591076e-05 | C4: =IF($A$1=0, 0, IF(B4<=$A$2, ($A$1/$A$2^2)*(2*$A$2*B4-B4^2), ($A$1/(1-$A$2)^2)*((1-2*$A$2)+2*$A$2*B4-B4^2))) -> 6.6882885e-06 | D4: =5*$A$3*(0.2969*SQRT(B4)-0.126*B4-0.3516*B4^2+0.2843*B4^3-0.1015*B4^4) -> 0.0020758254 | E4: =IF($A$1=0, 0, IF(B4<=$A$2, ($A$1/$A$2^2) *(2*$A$2-2*B4), ($A$1/(1-$A$2)^2)*(2*$A$2-2*B4))) -> 0.14998328 | F4: =IF($A$1=0, 0, ATAN(E4)) -> 0.14887359 | G4: =B4-D4*SIN(F4) -> -0.00026330423 | H4: =C4+D4*COS(F4) -> 0.0020595525 | I4: =B4+D4*SIN(F4) -> 0.00035248639 | J4: =C4-D4*COS(F4) -> -0.002046176 | M4: =IF($Q$1, C4, -0.2) -> -0.2 | S4: 0.38468481 | T4: =$R$2*(COS($R$1)+COS(S4)) -> 0.09309604 | U4: =IF($Q$2, $R$2*(SIN($R$1)+SIN(S4)), -0.2) -> -0.2
B5: 7.9272565e-05 | C5: =IF($A$1=0, 0, IF(B5<=$A$2, ($A$1/$A$2^2)*(2*$A$2*B5-B5^2), ($A$1/(1-$A$2)^2)*((1-2*$A$2)+2*$A$2*B5-B5^2))) -> 1.1889707e-05 | D5: =5*$A$3*(0.2969*SQRT(B5)-0.126*B5-0.3516*B5^2+0.2843*B5^3-0.1015*B5^4) -> 0.002765136 | E5: =IF($A$1=0, 0, IF(B5<=$A$2, ($A$1/$A$2^2) *(2*$A$2-2*B5), ($A$1/(1-$A$2)^2)*(2*$A$2-2*B5))) -> 0.14997027 | F5: =IF($A$1=0, 0, ATAN(E5)) -> 0.14886087 | G5: =B5-D5*SIN(F5) -> -0.00033082945 | H5: =C5+D5*COS(F5) -> 0.0027464451 | I5: =B5+D5*SIN(F5) -> 0.00048937458 | J5: =C5-D5*COS(F5) -> -0.0027226657 | M5: =IF($Q$1, C5, -0.2) -> -0.2 | S5: 0.51291309 | T5: =$R$2*(COS($R$1)+COS(S5)) -> 0.090394393 | U5: =IF($Q$2, $R$2*(SIN($R$1)+SIN(S5)), -0.2) -> -0.2
B6: 0.00012386246 | C6: =IF($A$1=0, 0, IF(B6<=$A$2, ($A$1/$A$2^2)*(2*$A$2*B6-B6^2), ($A$1/(1-$A$2)^2)*((1-2*$A$2)+2*$A$2*B6-B6^2))) -> 1.8576493e-05 | D6: =5*$A$3*(0.2969*SQRT(B6)-0.126*B6-0.3516*B6^2+0.2843*B6^3-0.1015*B6^4) -> 0.003453127 | E6: =IF($A$1=0, 0, IF(B6<=$A$2, ($A$1/$A$2^2) *(2*$A$2-2*B6), ($A$1/(1-$A$2)^2)*(2*$A$2-2*B6))) -> 0.14995355 | F6: =IF($A$1=0, 0, ATAN(E6)) -> 0.14884452 | G6: =B6-D6*SIN(F6) -> -0.00038822083 | H6: =C6+D6*COS(F6) -> 0.0034335226 | I6: =B6+D6*SIN(F6) -> 0.00063594575 | J6: =C6-D6*COS(F6) -> -0.0033963696 | M6: =IF($Q$1, C6, -0.2) -> -0.2 | S6: 0.64114136 | T6: =$R$2*(COS($R$1)+COS(S6)) -> 0.086997532 | U6: =IF($Q$2, $R$2*(SIN($R$1)+SIN(S6)), -0.2) -> -0.2
B7: 0.00017836033 | C7: =IF($A$1=0, 0, IF(B7<=$A$2, ($A$1/$A$2^2)*(2*$A$2*B7-B7^2), ($A$1/(1-$A$2)^2)*((1-2*$A$2)+2*$A$2*B7-B7^2))) -> 2.6748084e-05 | D7: =5*$A$3*(0.2969*SQRT(B7)-0.126*B7-0.3516*B7^2+0.2843*B7^3-0.1015*B7^4) -> 0.0041397959 | E7: =IF($A$1=0, 0, IF(B7<=$A$2, ($A$1/$A$2^2) *(2*$A$2-2*B7), ($A$1/(1-$A$2)^2)*(2*$A$2-2*B7))) -> 0.14993311 | F7: =IF($A$1=0, 0, ATAN(E7)) -> 0.14882453 | G7: =B7-D7*SIN(F7) -> -0.00043547106 | H7: =C7+D7*COS(F7) -> 0.0041207829 | I7: =B7+D7*SIN(F7) -> 0.00079219171 | J7: =C7-D7*COS(F7) -> -0.0040672867 | M7: =IF($Q$1, C7, -0.2) -> -0.2 | S7: 0.76936963 | T7: =$R$2*(COS($R$1)+COS(S7)) -> 0.082961234 | U7: =IF($Q$2, $R$2*(SIN($R$1)+SIN(S7)), -0.2) -> -0.2
B8: 0.00024276562 | C8: =IF($A$1=0, 0, IF(B8<=$A$2, ($A$1/$A$2^2)*(2*$A$2*B8-B8^2), ($A$1/(1-$A$2)^2)*((1-2*$A$2)+2*$A$2*B8-B8^2))) -> 3.6403792e-05 | D8: =5*$A$3*(0.2969*SQRT(B8)-0.126*B8-0.3516*B8^2+0.2843*B8^3-0.1015*B8^4) -> 0.0048251397 | E8: =IF($A$1=0, 0, IF(B8<=$A$2, ($A$1/$A$2^2) *(2*$A$2-2*B8), ($A$1/(1-$A$2)^2)*(2*$A$2-2*B8))) -> 0.14990896 | F8: =IF($A$1=0, 0, ATAN(E8)) -> 0.14880091 | G8: =B8-D8*SIN(F8) -> -0.00047257294 | H8: =C8+D8*COS(F8) -> 0.0048082236 | I8: =B8+D8*SIN(F8) -> 0.00095810417 | J8: =C8-D8*COS(F8) -> -0.004735416 | M8: =IF($Q$1, C8, -0.2) -> -0.2 | S8: 0.8975979 | T8: =$R$2*(COS($R$1)+COS(S8)) -> 0.078351774 | U8: =IF($Q$2, $R$2*(SIN($R$1)+SIN(S8)), -0.2) -> -0.2
B9: 0.00031707769 | C9: =IF($A$1=0, 0, IF(B9<=$A$2, ($A$1/$A$2^2)*(2*$A$2*B9-B9^2), ($A$1/(1-$A$2)^2)*((1-2*$A$2)+2*$A$2*B9-B9^2))) -> 4.7542803e-05 | D9: =5*$A$3*(0.2969*SQRT(B9)-0.126*B9-0.3516*B9^2+0.2843*B9^3-0.1015*B9^4) -> 0.0055091556 | E9: =IF($A$1=0, 0, IF(B9<=$A$2, ($A$1/$A$2^2) *(2*$A$2-2*B9), ($A$1/(1-$A$2)^2)*(2*$A$2-2*B9))) -> 0.1498811 | F9: =IF($A$1=0, 0, ATAN(E9)) -> 0.14877366 | G9: =B9-D9*SIN(F9) -> -0.00049951936 | H9: =C9+D9*COS(F9) -> 0.005495842 | I9: =B9+D9*SIN(F9) -> 0.0011336747 | J9: =C9-D9*COS(F9) -> -0.0054007564 | M9: =IF($Q$1, C9, -0.2) -> -0.2 | S9: 1.0258262 | T9: =$R$2*(COS($R$1)+COS(S9)) -> 0.073244839 | U9: =IF($Q$2, $R$2*(SIN($R$1)+SIN(S9)), -0.2) -> -0.2
B10: 0.00040129582 | C10: =IF($A$1=0, 0, IF(B10<=$A$2, ($A$1/$A$2^2)*(2*$A$2*B10-B10^2), ($A$1/(1-$A$2)^2)*((1-2*$A$2)+2*$A$2*B10-B10^2))) -> 6.0164178e-05 | D10: =5*$A$3*(0.2969*SQRT(B10)-0.126*B10-0.3516*B10^2+0.2843*B10^3-0.1015*B10^4) -> 0.0061918401 | E10: =IF($A$1=0, 0, IF(B10<=$A$2, ($A$1/$A$2^2) *(2*$A$2-2*B10), ($A$1/(1-$A$2)^2)*(2*$A$2-2*B10))) -> 0.14984951 | F10: =IF($A$1=0, 0, ATAN(E10)) -> 0.14874277 | G10: =B10-D10*SIN(F10) -> -0.00051630332 | H10: =C10+D10*COS(F10) -> 0.0061836351 | I10: =B10+D10*SIN(F10) -> 0.001318895 | J10: =C10-D10*COS(F10) -> -0.0060633067 | M10: =IF($Q$1, C10, -0.2) -> -0.2 | S10: 1.1540544 | T10: =$R$2*(COS($R$1)+COS(S10)) -> 0.067724286 | U10: =IF($Q$2, $R$2*(SIN($R$1)+SIN(S10)), -0.2) -> -0.2
B11: 0.00049541917 | C11: =IF($A$1=0, 0, IF(B11<=$A$2, ($A$1/$A$2^2)*(2*$A$2*B11-B11^2), ($A$1/(1-$A$2)^2)*((1-2*$A$2)+2*$A$2*B11-B11^2))) -> 7.4266855e-05 | D11: =5*$A$3*(0.2969*SQRT(B11)-0.126*B11-0.3516*B11^2+0.2843*B11^3-0.1015*B11^4) -> 0.0068731899 | E11: =IF($A$1=0, 0, IF(B11<=$A$2, ($A$1/$A$2^2) *(2*$A$2-2*B11), ($A$1/(1-$A$2)^2)*(2*$A$2-2*B11))) -> 0.14981422 | F11: =IF($A$1=0, 0, ATAN(E11)) -> 0.14870825 | G11: =B11-D11*SIN(F11) -> -0.00052291788 | H11: =C11+D11*COS(F11) -> 0.0068715993 | I11: =B11+D11*SIN(F11) -> 0.0015137562 | J11: =C11-D11*COS(F11) -> -0.0067230656 | M11: =IF($Q$1, C11, -0.2) -> -0.2 | S11: 1.2822827 | T11: =$R$2*(COS($R$1)+COS(S11)) -> 0.061880761 | U11: =IF($Q$2, $R$2*(SIN($R$1)+SIN(S11)), -0.2) -> -0.2
B12: 0.0005994468 | C12: =IF($A$1=0, 0, IF(B12<=$A$2, ($A$1/$A$2^2)*(2*$A$2*B12-B12^2), ($A$1/(1-$A$2)^2)*((1-2*$A$2)+2*$A$2*B12-B12^2))) -> 8.9849644e-05 | D12: =5*$A$3*(0.2969*SQRT(B12)-0.126*B12-0.3516*B12^2+0.2843*B12^3-0.1015*B12^4) -> 0.0075532013 | E12: =IF($A$1=0, 0, IF(B12<=$A$2, ($A$1/$A$2^2) *(2*$A$2-2*B12), ($A$1/(1-$A$2)^2)*(2*$A$2-2*B12))) -> 0.14977521 | F12: =IF($A$1=0, 0, ATAN(E12)) -> 0.14867009 | G12: =B12-D12*SIN(F12) -> -0.00051935625 | H12: =C12+D12*COS(F12) -> 0.0075597311 | I12: =B12+D12*SIN(F12) -> 0.0017182498 | J12: =C12-D12*COS(F12) -> -0.0073800318 | M12: =IF($Q$1, C12, -0.2) -> -0.2 | S12: 1.410511 | T12: =$R$2*(COS($R$1)+COS(S12)) -> 0.055810216 | U12: =IF($Q$2, $R$2*(SIN($R$1)+SIN(S12)), -0.2) -> -0.2
B13: 0.00071337768 | C13: =IF($A$1=0, 0, IF(B13<=$A$2, ($A$1/$A$2^2)*(2*$A$2*B13-B13^2), ($A$1/(1-$A$2)^2)*((1-2*$A$2)+2*$A$2*B13-B13^2))) -> 0.00010691123 | D13: =5*$A$3*(0.2969*SQRT(B13)-0.126*B13-0.3516*B13^2+0.2843*B13^3-0.1015*B13^4) -> 0.0082318704 | E13: =IF($A$1=0, 0, IF(B13<=$A$2, ($A$1/$A$2^2) *(2*$A$2-2*B13), ($A$1/(1-$A$2)^2)*(2*$A$2-2*B13))) -> 0.14973248 | F13: =IF($A$1=0, 0, ATAN(E13)) -> 0.14862831 | G13: =B13-D13*SIN(F13) -> -0.0005056117 | H13: =C13+D13*COS(F13) -> 0.0082480263 | I13: =B13+D13*SIN(F13) -> 0.0019323671 | J13: =C13-D13*COS(F13) -> -0.0080342039 | M13: =IF($Q$1, C13, -0.2) -> -0.2 | S13: 1.5387393 | T13: =$R$2*(COS($R$1)+COS(S13)) -> 0.049612328 | U13: =IF($Q$2, $R$2*(SIN($R$1)+SIN(S13)), -0.2) -> -0.2
B14: 0.00083721069 | C14: =IF($A$1=0, 0, IF(B14<=$A$2, ($A$1/$A$2^2)*(2*$A$2*B14-B14^2), ($A$1/(1-$A$2)^2)*((1-2*$A$2)+2*$A$2*B14-B14^2))) -> 0.00012545018 | D14: =5*$A$3*(0.2969*SQRT(B14)-0.126*B14-0.3516*B14^2+0.2843*B14^3-0.1015*B14^4) -> 0.0089091932 | E14: =IF($A$1=0, 0, IF(B14<=$A$2, ($A$1/$A$2^2) *(2*$A$2-2*B14), ($A$1/(1-$A$2)^2)*(2*$A$2-2*B14))) -> 0.14968605 | F14: =IF($A$1=0, 0, ATAN(E14)) -> 0.14858289 | G14: =B14-D14*SIN(F14) -> -0.00048167762 | H14: =C14+D14*COS(F14) -> 0.0089364806 | I14: =B14+D14*SIN(F14) -> 0.002156099 | J14: =C14-D14*COS(F14) -> -0.0086855802 | M14: =IF($Q$1, C14, -0.2) -> -0.2 | S14: 1.6669675 | T14: =$R$2*(COS($R$1)+COS(S14)) -> 0.043388866 | U14: =IF($Q$2, $R$2*(SIN($R$1)+SIN(S14)), -0.2) -> -0.2
B15: 0.00097094459 | C15: =IF($A$1=0, 0, IF(B15<=$A$2, ($A$1/$A$2^2)*(2*$A$2*B15-B15^2), ($A$1/(1-$A$2)^2)*((1-2*$A$2)+2*$A$2*B15-B15^2))) -> 0.00014546493 | D15: =5*$A$3*(0.2969*SQRT(B15)-0.126*B15-0.3516*B15^2+0.2843*B15^3-0.1015*B15^4) -> 0.0095851654 | E15: =IF($A$1=0, 0, IF(B15<=$A$2, ($A$1/$A$2^2) *(2*$A$2-2*B15), ($A$1/(1-$A$2)^2)*(2*$A$2-2*B15))) -> 0.1496359 | F15: =IF($A$1=0, 0, ATAN(E15)) -> 0.14853384 | G15: =B15-D15*SIN(F15) -> -0.00044754748 | H15: =C15+D15*COS(F15) -> 0.0096250892 | I15: =B15+D15*SIN(F15) -> 0.0023894367 | J15: =C15-D15*COS(F15) -> -0.0093341593 | M15: =IF($Q$1, C15, -0.2) -> -0.2 | S15: 1.7951958 | T15: =$R$2*(COS($R$1)+COS(S15)) -> 0.03724202 | U15: =IF($Q$2, $R$2*(SIN($R$1)+SIN(S15)), -0.2) -> -0.2
... B50: 0.011872429 | C50: =IF($A$1=0, 0, IF(B50<=$A$2, ($A$1/$A$2^2)*(2*$A$2*B50-B50^2), ($A$1/(1-$A$2)^2)*((1-2*$A$2)+2*$A$2*B50-B50^2))) -> 0.0017544354 | D50: =5*$A$3*(0.2969*SQRT(B50)-0.126*B50-0.3516*B50^2+0.2843*B50^3-0.1015*B50^4) -> 0.032345684 | E50: =IF($A$1=0, 0, IF(B50<=$A$2, ($A$1/$A$2^2) *(2*$A$2-2*B50), ($A$1/(1-$A$2)^2)*(2*$A$2-2*B50))) -> 0.14554784 | F50: =IF($A$1=0, 0, ATAN(E50)) -> 0.14453294 | G50: =B50-D50*SIN(F50) -> 0.0072136723 | H50: =C50+D50*COS(F50) -> 0.03376286 | I50: =B50+D50*SIN(F50) -> 0.016531186 | J50: =C50-D50*COS(F50) -> -0.030253989 | M50: =IF($Q$1, C50, -0.2) -> -0.2 | S50: 6.2831853 | T50: =$R$2*(COS($R$1)+COS(S50)) -> 0.096647335 | U50: =IF($Q$2, $R$2*(SIN($R$1)+SIN(S50)), -0.2) -> -0.2
B51: 0.012360952 | C51: =IF($A$1=0, 0, IF(B51<=$A$2, ($A$1/$A$2^2)*(2*$A$2*B51-B51^2), ($A$1/(1-$A$2)^2)*((1-2*$A$2)+2*$A$2*B51-B51^2))) -> 0.0018254941 | D51: =5*$A$3*(0.2969*SQRT(B51)-0.126*B51-0.3516*B51^2+0.2843*B51^3-0.1015*B51^4) -> 0.032968552 | E51: =IF($A$1=0, 0, IF(B51<=$A$2, ($A$1/$A$2^2) *(2*$A$2-2*B51), ($A$1/(1-$A$2)^2)*(2*$A$2-2*B51))) -> 0.14536464 | F51: =IF($A$1=0, 0, ATAN(E51)) -> 0.14435354 | G51: =B51-D51*SIN(F51) -> 0.0076183363 | H51: =C51+D51*COS(F51) -> 0.034451144 | I51: =B51+D51*SIN(F51) -> 0.017103568 | J51: =C51-D51*COS(F51) -> -0.030800155 | M51: =IF($Q$1, C51, -0.2) -> -0.2
B52: 0.012859262 | C52: =IF($A$1=0, 0, IF(B52<=$A$2, ($A$1/$A$2^2)*(2*$A$2*B52-B52^2), ($A$1/(1-$A$2)^2)*((1-2*$A$2)+2*$A$2*B52-B52^2))) -> 0.0018978841 | D52: =5*$A$3*(0.2969*SQRT(B52)-0.126*B52-0.3516*B52^2+0.2843*B52^3-0.1015*B52^4) -> 0.033589777 | E52: =IF($A$1=0, 0, IF(B52<=$A$2, ($A$1/$A$2^2) *(2*$A$2-2*B52), ($A$1/(1-$A$2)^2)*(2*$A$2-2*B52))) -> 0.14517778 | F52: =IF($A$1=0, 0, ATAN(E52)) -> 0.14417053 | G52: =B52-D52*SIN(F52) -> 0.0080333641 | H52: =C52+D52*COS(F52) -> 0.035139181 | I52: =B52+D52*SIN(F52) -> 0.017685159 | J52: =C52-D52*COS(F52) -> -0.031343413 | M52: =IF($Q$1, C52, -0.2) -> -0.2
B53: 0.013367353 | C53: =IF($A$1=0, 0, IF(B53<=$A$2, ($A$1/$A$2^2)*(2*$A$2*B53-B53^2), ($A$1/(1-$A$2)^2)*((1-2*$A$2)+2*$A$2*B53-B53^2))) -> 0.0019715993 | D53: =5*$A$3*(0.2969*SQRT(B53)-0.126*B53-0.3516*B53^2+0.2843*B53^3-0.1015*B53^4) -> 0.034209347 | E53: =IF($A$1=0, 0, IF(B53<=$A$2, ($A$1/$A$2^2) *(2*$A$2-2*B53), ($A$1/(1-$A$2)^2)*(2*$A$2-2*B53))) -> 0.14498724 | F53: =IF($A$1=0, 0, ATAN(E53)) -> 0.14398393 | G53: =B53-D53*SIN(F53) -> 0.0084587582 | H53: =C53+D53*COS(F53) -> 0.035826955 | I53: =B53+D53*SIN(F53) -> 0.018275948 | J53: =C53-D53*COS(F53) -> -0.031883757 | M53: =IF($Q$1, C53, -0.2) -> -0.2
B54: 0.013885221 | C54: =IF($A$1=0, 0, IF(B54<=$A$2, ($A$1/$A$2^2)*(2*$A$2*B54-B54^2), ($A$1/(1-$A$2)^2)*((1-2*$A$2)+2*$A$2*B54-B54^2))) -> 0.0020466333 | D54: =5*$A$3*(0.2969*SQRT(B54)-0.126*B54-0.3516*B54^2+0.2843*B54^3-0.1015*B54^4) -> 0.034827252 | E54: =IF($A$1=0, 0, IF(B54<=$A$2, ($A$1/$A$2^2) *(2*$A$2-2*B54), ($A$1/(1-$A$2)^2)*(2*$A$2-2*B54))) -> 0.14479304 | F54: =IF($A$1=0, 0, ATAN(E54)) -> 0.14379372 | G54: =B54-D54*SIN(F54) -> 0.0088945209 | H54: =C54+D54*COS(F54) -> 0.03651445 | I54: =B54+D54*SIN(F54) -> 0.018875921 | J54: =C54-D54*COS(F54) -> -0.032421183 | M54: =IF($Q$1, C54, -0.2) -> -0.2
B55: 0.01441286 | C55: =IF($A$1=0, 0, IF(B55<=$A$2, ($A$1/$A$2^2)*(2*$A$2*B55-B55^2), ($A$1/(1-$A$2)^2)*((1-2*$A$2)+2*$A$2*B55-B55^2))) -> 0.0021229796 | D55: =5*$A$3*(0.2969*SQRT(B55)-0.126*B55-0.3516*B55^2+0.2843*B55^3-0.1015*B55^4) -> 0.035443479 | E55: =IF($A$1=0, 0, IF(B55<=$A$2, ($A$1/$A$2^2) *(2*$A$2-2*B55), ($A$1/(1-$A$2)^2)*(2*$A$2-2*B55))) -> 0.14459518 | F55: =IF($A$1=0, 0, ATAN(E55)) -> 0.14359991 | G55: =B55-D55*SIN(F55) -> 0.0093406543 | H55: =C55+D55*COS(F55) -> 0.037201647 | I55: =B55+D55*SIN(F55) -> 0.019485067 | J55: =C55-D55*COS(F55) -> -0.032955688 | M55: =IF($Q$1, C55, -0.2) -> -0.2
B56: 0.014950266 | C56: =IF($A$1=0, 0, IF(B56<=$A$2, ($A$1/$A$2^2)*(2*$A$2*B56-B56^2), ($A$1/(1-$A$2)^2)*((1-2*$A$2)+2*$A$2*B56-B56^2))) -> 0.0022006317 | D56: =5*$A$3*(0.2969*SQRT(B56)-0.126*B56-0.3516*B56^2+0.2843*B56^3-0.1015*B56^4) -> 0.036058017 | E56: =IF($A$1=0, 0, IF(B56<=$A$2, ($A$1/$A$2^2) *(2*$A$2-2*B56), ($A$1/(1-$A$2)^2)*(2*$A$2-2*B56))) -> 0.14439365 | F56: =IF($A$1=0, 0, ATAN(E56)) -> 0.14340251 | G56: =B56-D56*SIN(F56) -> 0.0097971605 | H56: =C56+D56*COS(F56) -> 0.03788853 | I56: =B56+D56*SIN(F56) -> 0.020103372 | J56: =C56-D56*COS(F56) -> -0.033487267 | M56: =IF($Q$1, C56, -0.2) -> -0.2
B57: 0.015497433 | C57: =IF($A$1=0, 0, IF(B57<=$A$2, ($A$1/$A$2^2)*(2*$A$2*B57-B57^2), ($A$1/(1-$A$2)^2)*((1-2*$A$2)+2*$A$2*B57-B57^2))) -> 0.0022795831 | D57: =5*$A$3*(0.2969*SQRT(B57)-0.126*B57-0.3516*B57^2+0.2843*B57^3-0.1015*B57^4) -> 0.036670854 | E57: =IF($A$1=0, 0, IF(B57<=$A$2, ($A$1/$A$2^2) *(2*$A$2-2*B57), ($A$1/(1-$A$2)^2)*(2*$A$2-2*B57))) -> 0.14418846 | F57: =IF($A$1=0, 0, ATAN(E57)) -> 0.1432015 | G57: =B57-D57*SIN(F57) -> 0.010264041 | H57: =C57+D57*COS(F57) -> 0.038575081 | I57: =B57+D57*SIN(F57) -> 0.020730825 | J57: =C57-D57*COS(F57) -> -0.034015915 | M57: =IF($Q$1, C57, -0.2) -> -0.2
B58: 0.016054356 | C58: =IF($A$1=0, 0, IF(B58<=$A$2, ($A$1/$A$2^2)*(2*$A$2*B58-B58^2), ($A$1/(1-$A$2)^2)*((1-2*$A$2)+2*$A$2*B58-B58^2))) -> 0.0023598267 | D58: =5*$A$3*(0.2969*SQRT(B58)-0.126*B58-0.3516*B58^2+0.2843*B58^3-0.1015*B58^4) -> 0.037281979 | E58: =IF($A$1=0, 0, IF(B58<=$A$2, ($A$1/$A$2^2) *(2*$A$2-2*B58), ($A$1/(1-$A$2)^2)*(2*$A$2-2*B58))) -> 0.14397962 | F58: =IF($A$1=0, 0, ATAN(E58)) -> 0.14299691 | G58: =B58-D58*SIN(F58) -> 0.010741299 | H58: =C58+D58*COS(F58) -> 0.039261281 | I58: =B58+D58*SIN(F58) -> 0.021367413 | J58: =C58-D58*COS(F58) -> -0.034541628 | M58: =IF($Q$1, C58, -0.2) -> -0.2
B59: 0.016621029 | C59: =IF($A$1=0, 0, IF(B59<=$A$2, ($A$1/$A$2^2)*(2*$A$2*B59-B59^2), ($A$1/(1-$A$2)^2)*((1-2*$A$2)+2*$A$2*B59-B59^2))) -> 0.0024413558 | D59: =5*$A$3*(0.2969*SQRT(B59)-0.126*B59-0.3516*B59^2+0.2843*B59^3-0.1015*B59^4) -> 0.037891378 | E59: =IF($A$1=0, 0, IF(B59<=$A$2, ($A$1/$A$2^2) *(2*$A$2-2*B59), ($A$1/(1-$A$2)^2)*(2*$A$2-2*B59))) -> 0.14376711 | F59: =IF($A$1=0, 0, ATAN(E59)) -> 0.14278871 | G59: =B59-D59*SIN(F59) -> 0.011228934 | H59: =C59+D59*COS(F59) -> 0.039947113 | I59: =B59+D59*SIN(F59) -> 0.022013123 | J59: =C59-D59*COS(F59) -> -0.035064401 | M59: =IF($Q$1, C59, -0.2) -> -0.2
B60: 0.017197446 | C60: =IF($A$1=0, 0, IF(B60<=$A$2, ($A$1/$A$2^2)*(2*$A$2*B60-B60^2), ($A$1/(1-$A$2)^2)*((1-2*$A$2)+2*$A$2*B60-B60^2))) -> 0.0025241634 | D60: =5*$A$3*(0.2969*SQRT(B60)-0.126*B60-0.3516*B60^2+0.2843*B60^3-0.1015*B60^4) -> 0.038499039 | E60: =IF($A$1=0, 0, IF(B60<=$A$2, ($A$1/$A$2^2) *(2*$A$2-2*B60), ($A$1/(1-$A$2)^2)*(2*$A$2-2*B60))) -> 0.14355096 | F60: =IF($A$1=0, 0, ATAN(E60)) -> 0.14257693 | G60: =B60-D60*SIN(F60) -> 0.01172695 | H60: =C60+D60*COS(F60) -> 0.040632557 | I60: =B60+D60*SIN(F60) -> 0.022667942 | J60: =C60-D60*COS(F60) -> -0.03558423 | M60: =IF($Q$1, C60, -0.2) -> -0.2
B61: 0.017783602 | C61: =IF($A$1=0, 0, IF(B61<=$A$2, ($A$1/$A$2^2)*(2*$A$2*B61-B61^2), ($A$1/(1-$A$2)^2)*((1-2*$A$2)+2*$A$2*B61-B61^2))) -> 0.0026082422 | D61: =5*$A$3*(0.2969*SQRT(B61)-0.126*B61-0.3516*B61^2+0.2843*B61^3-0.1015*B61^4) -> 0.03910495 | E61: =IF($A$1=0, 0, IF(B61<=$A$2, ($A$1/$A$2^2) *(2*$A$2-2*B61), ($A$1/(1-$A$2)^2)*(2*$A$2-2*B61))) -> 0.14333115 | F61: =IF($A$1=0, 0, ATAN(E61)) -> 0.14236155 | G61: =B61-D61*SIN(F61) -> 0.012235346 | H61: =C61+D61*COS(F61) -> 0.041317595 | I61: =B61+D61*SIN(F61) -> 0.023331858 | J61: =C61-D61*COS(F61) -> -0.036101111 | M61: =IF($Q$1, C61, -0.2) -> -0.2
B62: 0.018379491 | C62: =IF($A$1=0, 0, IF(B62<=$A$2, ($A$1/$A$2^2)*(2*$A$2*B62-B62^2), ($A$1/(1-$A$2)^2)*((1-2*$A$2)+2*$A$2*B62-B62^2))) -> 0.0026935851 | D62: =5*$A$3*(0.2969*SQRT(B62)-0.126*B62-0.3516*B62^2+0.2843*B62^3-0.1015*B62^4) -> 0.039709099 | E62: =IF($A$1=0, 0, IF(B62<=$A$2, ($A$1/$A$2^2) *(2*$A$2-2*B62), ($A$1/(1-$A$2)^2)*(2*$A$2-2*B62))) -> 0.14310769 | F62: =IF($A$1=0, 0, ATAN(E62)) -> 0.14214258 | G62: =B62-D62*SIN(F62) -> 0.012754125 | H62: =C62+D62*COS(F62) -> 0.042002208 | I62: =B62+D62*SIN(F62) -> 0.024004857 | J62: =C62-D62*COS(F62) -> -0.036615037 | M62: =IF($Q$1, C62, -0.2) -> -0.2
... B500: 1 | C500: =IF($A$1=0, 0, IF(B500<=$A$2, ($A$1/$A$2^2)*(2*$A$2*B500-B500^2), ($A$1/(1-$A$2)^2)*((1-2*$A$2)+2*$A$2*B500-B500^2))) -> 9.2518585e-18 | D500: =5*$A$3*(0.2969*SQRT(B500)-0.126*B500-0.3516*B500^2+0.2843*B500^3-0.1015*B500^4) -> 0.002205 | E500: =IF($A$1=0, 0, IF(B500<=$A$2, ($A$1/$A$2^2) *(2*$A$2-2*B500), ($A$1/(1-$A$2)^2)*(2*$A$2-2*B500))) -> -0.1 | F500: =IF($A$1=0, 0, ATAN(E500)) -> -0.099668652 | G500: =B500-D500*SIN(F500) -> 1.0002194 | H500: =C500+D500*COS(F500) -> 0.002194057 | I500: =B500+D500*SIN(F500) -> 0.99978059 | J500: =C500-D500*COS(F500) -> -0.002194057 | M500: =IF($Q$1, C500, -0.2) -> -0.2

Sheet NACA_4-digit
A1: BACK | E1: Name | F1: =Data1!O1*1000+Data1!O2*100+Data1!O3 -> 3421
E2: Maximum Camber | F2: =IF(Data1!$P$1=1, "-", Data1!A1) -> 0.03 | H2: Leading-Edge Radius | I2: =Data1!R2 -> 0.048592473
E3: Position of Camber | F3: =IF(Data1!$P$1=1, "-", Data1!A2) -> 0.4 | H3: Trailing-Edge Angle | I3: =DEGREES(2*ATAN(1.16925*F4)) -> 27.59124
E4: Maximum Thickness | F4: =Data1!A3 -> 0.21

Sheet Data2
A1: 1000 | B1: {=1-COS((_xlfn.SEQUENCE(500,1,0,1)*PI())/(2*(500-1)))} -> 0 | C1: =IF(AND($Q$1=2, $A$3=1), 0, 5*($A$4/100)*(0.2969*SQRT(B1)-0.126*B1-0.3516*(B1^2)+0.2843*(B1^3)-0.1015*(B1^4))) -> 0 | D1: =IF($Q$1=1, IF(B1<$A$8, ($A$10/6)*((B1^3)-3*$A$8*(B1^2)+($A$8^2)*(3-$A$8)*B1), (($A$10*($A$8^3))/6)*(1-B1)), " ") -> 0 | E1: =IF($Q$1=1,IF(B1<$A$8, ($A$10/6)*(3*(B1^2)-6*$A$8*B1+($A$8^2)*(3-$A$8)), -($A$10*($A$8^3))/6), " ") -> 0.19512811 | F1: =IF($Q$1=1, ATAN(E1), " ") -> 0.19270669 | G1: =IF($Q$1=2, IF(A3<>1, IF(B1<$A$11, ($A$12/6)*((B1-$A$11)^3-$A$13*((1-$A$11)^3)*B1-($A$11^3)*B1+$A$11^3), ($A$12/6)*($A$13*(B1-$A$11)^3-$A$13*((1-$A$11)^3)*B1-($A$11^3)*B1+$A$11^3)), 0), " ") | H1: =IF($Q$1=2, IF(A3<>1, IF(B1<$A$11, ($A$12/6)*(3*(B1-$A$11)^2-$A$13*((1-$A$11)^3)-($A$11^3)), ($A$12/6)*(3*$A$13*(B1-$A$11)^2-$A$13*((1-$A$11)^3)-($A$11^3))),0 ), " ") | I1: =IF($Q$1=2, IF(A3<>1, ATAN(H1), 0), " ") | J1: =IF($Q$1=1, D1, G1) -> 0 | K1: =IF($Q$1=1, F1, I1) -> 0.19270669 | L1: =B1-C1*SIN(K1) -> 0 | M1: =J1+C1*COS(K1) -> 0 | N1: =B1+C1*SIN(K1) -> 0 | O1: =J1-C1*COS(K1) -> 0 | P1: 0.2 | Q1: 1 | R1: =IF($T$1, J1, -0.2) -> -0.2 | T1: FALSE | U1: =ATAN(K1) -> 0.19037303 | V1: {=_xlfn.SEQUENCE(50, 1, 0, (2*PI())/(50-1))} -> 0 | W1: =$U$2*(COS($U$1)+COS(V1)) -> 0.031447203 | X1: =IF($T$2, $U$2*(SIN($U$1)+SIN(V1)), -0.2) -> -0.2
A2: 1 | B2: 4.9545967e-06 | C2: =IF(AND($Q$1=2, $A$3=1), 0, 5*($A$4/100)*(0.2969*SQRT(B2)-0.126*B2-0.3516*(B2^2)+0.2843*(B2^3)-0.1015*(B2^4))) -> 0.00039614589 | D2: =IF($Q$1=1, IF(B2<$A$8, ($A$10/6)*((B2^3)-3*$A$8*(B2^2)+($A$8^2)*(3-$A$8)*B2), (($A$10*($A$8^3))/6)*(1-B2)), " ") -> 9.6674141e-07 | E2: =IF($Q$1=1,IF(B2<$A$8, ($A$10/6)*(3*(B2^2)-6*$A$8*B2+($A$8^2)*(3-$A$8)), -($A$10*($A$8^3))/6), " ") -> 0.19511209 | F2: =IF($Q$1=1, ATAN(E2), " ") -> 0.19269126 | G2: =IF($Q$1=2, IF(A4<>1, IF(B2<$A$11, ($A$12/6)*((B2-$A$11)^3-$A$13*((1-$A$11)^3)*B2-($A$11^3)*B2+$A$11^3), ($A$12/6)*($A$13*(B2-$A$11)^3-$A$13*((1-$A$11)^3)*B2-($A$11^3)*B2+$A$11^3)), 0), " ") | H2: =IF($Q$1=2, IF(A4<>1, IF(B2<$A$11, ($A$12/6)*(3*(B2-$A$11)^2-$A$13*((1-$A$11)^3)-($A$11^3)), ($A$12/6)*(3*$A$13*(B2-$A$11)^2-$A$13*((1-$A$11)^3)-($A$11^3))),0 ), " ") | I2: =IF($Q$1=2, IF(A4<>1, ATAN(H2), 0), " ") | J2: =IF($Q$1=1, D2, G2) -> 9.6674141e-07 | K2: =IF($Q$1=1, F2, I2) -> 0.19269126 | L2: =B2-C2*SIN(K2) -> -7.0907752e-05 | M2: =J2+C2*COS(K2) -> 0.00038978092 | N2: =B2+C2*SIN(K2) -> 8.0816945e-05 | O2: =J2-C2*COS(K2) -> -0.00038784744 | P2: =P1-(P1-P1*SQRT(P1/3)-$A$5)/(1-SQRT(3*P1)/2) -> 0.12107052 | R2: =IF($T$1, J2, -0.2) -> -0.2 | T2: FALSE | U2: =(0.2969^2/2)*(A7/0.2)^2 -> 0.01586693 | V2: 0.12822827 | W2: =$U$2*(COS($U$1)+COS(V2)) -> 0.031316936 | X2: =IF($T$2, $U$2*(SIN($U$1)+SIN(V2)), -0.2) -> -0.2
A3: 2 | B3: 1.9818338e-05 | C3: =IF(AND($Q$1=2, $A$3=1), 0, 5*($A$4/100)*(0.2969*SQRT(B3)-0.126*B3-0.3516*(B3^2)+0.2843*(B3^3)-0.1015*(B3^4))) -> 0.00079154159 | D3: =IF($Q$1=1, IF(B3<$A$8, ($A$10/6)*((B3^3)-3*$A$8*(B3^2)+($A$8^2)*(3-$A$8)*B3), (($A$10*($A$8^3))/6)*(1-B3)), " ") -> 3.8664799e-06 | E3: =IF($Q$1=1,IF(B3<$A$8, ($A$10/6)*(3*(B3^2)-6*$A$8*B3+($A$8^2)*(3-$A$8)), -($A$10*($A$8^3))/6), " ") -> 0.19506404 | F3: =IF($Q$1=1, ATAN(E3), " ") -> 0.19264497 | G3: =IF($Q$1=2, IF(A5<>1, IF(B3<$A$11, ($A$12/6)*((B3-$A$11)^3-$A$13*((1-$A$11)^3)*B3-($A$11^3)*B3+$A$11^3), ($A$12/6)*($A$13*(B3-$A$11)^3-$A$13*((1-$A$11)^3)*B3-($A$11^3)*B3+$A$11^3)), 0), " ") | H3: =IF($Q$1=2, IF(A5<>1, IF(B3<$A$11, ($A$12/6)*(3*(B3-$A$11)^2-$A$13*((1-$A$11)^3)-($A$11^3)), ($A$12/6)*(3*$A$13*(B3-$A$11)^2-$A$13*((1-$A$11)^3)-($A$11^3))),0 ), " ") | I3: =IF($Q$1=2, IF(A5<>1, ATAN(H3), 0), " ") | J3: =IF($Q$1=1, D3, G3) -> 3.8664799e-06 | K3: =IF($Q$1=1, F3, I3) -> 0.19264497 | L3: =B3-C3*SIN(K3) -> -0.00013172674 | M3: =J3+C3*COS(K3) -> 0.00078076556 | N3: =B3+C3*SIN(K3) -> 0.00017136341 | O3: =J3-C3*COS(K3) -> -0.0007730326 | P3: =P2-(P2-P2*SQRT(P2/3)-$A$5)/(1-SQRT(3*P2)/2) -> 0.12572418 | R3: =IF($T$1, J3, -0.2) -> -0.2 | V3: 0.25645654 | W3: =$U$2*(COS($U$1)+COS(V3)) -> 0.030928273 | X3: =IF($T$2, $U$2*(SIN($U$1)+SIN(V3)), -0.2) -> -0.2
A4: 12 | B4: 4.4591076e-05 | C4: =IF(AND($Q$1=2, $A$3=1), 0, 5*($A$4/100)*(0.2969*SQRT(B4)-0.126*B4-0.3516*(B4^2)+0.2843*(B4^3)-0.1015*(B4^4))) -> 0.0011861859 | D4: =IF($Q$1=1, IF(B4<$A$8, ($A$10/6)*((B4^3)-3*$A$8*(B4^2)+($A$8^2)*(3-$A$8)*B4), (($A$10*($A$8^3))/6)*(1-B4)), " ") -> 8.6977585e-06 | E4: =IF($Q$1=1,IF(B4<$A$8, ($A$10/6)*(3*(B4^2)-6*$A$8*B4+($A$8^2)*(3-$A$8)), -($A$10*($A$8^3))/6), " ") -> 0.19498397 | F4: =IF($Q$1=1, ATAN(E4), " ") -> 0.19256783 | G4: =IF($Q$1=2, IF(A6<>1, IF(B4<$A$11, ($A$12/6)*((B4-$A$11)^3-$A$13*((1-$A$11)^3)*B4-($A$11^3)*B4+$A$11^3), ($A$12/6)*($A$13*(B4-$A$11)^3-$A$13*((1-$A$11)^3)*B4-($A$11^3)*B4+$A$11^3)), 0), " ") | H4: =IF($Q$1=2, IF(A6<>1, IF(B4<$A$11, ($A$12/6)*(3*(B4-$A$11)^2-$A$13*((1-$A$11)^3)-($A$11^3)), ($A$12/6)*(3*$A$13*(B4-$A$11)^2-$A$13*((1-$A$11)^3)-($A$11^3))),0 ), " ") | I4: =IF($Q$1=2, IF(A6<>1, ATAN(H4), 0), " ") | J4: =IF($Q$1=1, D4, G4) -> 8.6977585e-06 | K4: =IF($Q$1=1, F4, I4) -> 0.19256783 | L4: =B4-C4*SIN(K4) -> -0.00018242107 | M4: =J4+C4*COS(K4) -> 0.0011729583 | N4: =B4+C4*SIN(K4) -> 0.00027160322 | O4: =J4-C4*COS(K4) -> -0.0011555628 | P4: =P3-(P3-P3*SQRT(P3/3)-$A$5)/(1-SQRT(3*P3)/2) -> 0.12574351 | R4: =IF($T$1, J4, -0.2) -> -0.2 | V4: 0.38468481 | W4: =$U$2*(COS($U$1)+COS(V4)) -> 0.030287596 | X4: =IF($T$2, $U$2*(SIN($U$1)+SIN(V4)), -0.2) -> -0.2
A5: =0.05*$A$3 -> 0.1 | B5: 7.9272565e-05 | C5: =IF(AND($Q$1=2, $A$3=1), 0, 5*($A$4/100)*(0.2969*SQRT(B5)-0.126*B5-0.3516*(B5^2)+0.2843*(B5^3)-0.1015*(B5^4))) -> 0.0015800777 | D5: =IF($Q$1=1, IF(B5<$A$8, ($A$10/6)*((B5^3)-3*$A$8*(B5^2)+($A$8^2)*(3-$A$8)*B5), (($A$10*($A$8^3))/6)*(1-B5)), " ") -> 1.5458149e-05 | E5: =IF($Q$1=1,IF(B5<$A$8, ($A$10/6)*(3*(B5^2)-6*$A$8*B5+($A$8^2)*(3-$A$8)), -($A$10*($A$8^3))/6), " ") -> 0.1948719 | F5: =IF($Q$1=1, ATAN(E5), " ") -> 0.19245986 | G5: =IF($Q$1=2, IF(A7<>1, IF(B5<$A$11, ($A$12/6)*((B5-$A$11)^3-$A$13*((1-$A$11)^3)*B5-($A$11^3)*B5+$A$11^3), ($A$12/6)*($A$13*(B5-$A$11)^3-$A$13*((1-$A$11)^3)*B5-($A$11^3)*B5+$A$11^3)), 0), " ") | H5: =IF($Q$1=2, IF(A7<>1, IF(B5<$A$11, ($A$12/6)*(3*(B5-$A$11)^2-$A$13*((1-$A$11)^3)-($A$11^3)), ($A$12/6)*(3*$A$13*(B5-$A$11)^2-$A$13*((1-$A$11)^3)-($A$11^3))),0 ), " ") | I5: =IF($Q$1=2, IF(A7<>1, ATAN(H5), 0), " ") | J5: =IF($Q$1=1, D5, G5) -> 1.5458149e-05 | K5: =IF($Q$1=1, F5, I5) -> 0.19245986 | L5: =B5-C5*SIN(K5) -> -0.00022295509 | M5: =J5+C5*COS(K5) -> 0.0015663624 | N5: =B5+C5*SIN(K5) -> 0.00038150022 | O5: =J5-C5*COS(K5) -> -0.0015354461 | P5: =P4-(P4-P4*SQRT(P4/3)-$A$5)/(1-SQRT(3*P4)/2) -> 0.12574351 | R5: =IF($T$1, J5, -0.2) -> -0.2 | V5: 0.51291309 | W5: =$U$2*(COS($U$1)+COS(V5)) -> 0.029405426 | X5: =IF($T$2, $U$2*(SIN($U$1)+SIN(V5)), -0.2) -> -0.2
A6: =IF(Q1=1, A2/100, 0.02) -> 0.01 | B6: 0.00012386246 | C6: =IF(AND($Q$1=2, $A$3=1), 0, 5*($A$4/100)*(0.2969*SQRT(B6)-0.126*B6-0.3516*(B6^2)+0.2843*(B6^3)-0.1015*(B6^4))) -> 0.0019732154 | D6: =IF($Q$1=1, IF(B6<$A$8, ($A$10/6)*((B6^3)-3*$A$8*(B6^2)+($A$8^2)*(3-$A$8)*B6), (($A$10*($A$8^3))/6)*(1-B6)), " ") -> 2.4144256e-05 | E6: =IF($Q$1=1,IF(B6<$A$8, ($A$10/6)*(3*(B6^2)-6*$A$8*B6+($A$8^2)*(3-$A$8)), -($A$10*($A$8^3))/6), " ") -> 0.19472785 | F6: =IF($Q$1=1, ATAN(E6), " ") -> 0.19232109 | G6: =IF($Q$1=2, IF(A8<>1, IF(B6<$A$11, ($A$12/6)*((B6-$A$11)^3-$A$13*((1-$A$11)^3)*B6-($A$11^3)*B6+$A$11^3), ($A$12/6)*($A$13*(B6-$A$11)^3-$A$13*((1-$A$11)^3)*B6-($A$11^3)*B6+$A$11^3)), 0), " ") | H6: =IF($Q$1=2, IF(A8<>1, IF(B6<$A$11, ($A$12/6)*(3*(B6-$A$11)^2-$A$13*((1-$A$11)^3)-($A$11^3)), ($A$12/6)*(3*$A$13*(B6-$A$11)^2-$A$13*((1-$A$11)^3)-($A$11^3))),0 ), " ") | I6: =IF($Q$1=2, IF(A8<>1, ATAN(H6), 0), " ") | J6: =IF($Q$1=1, D6, G6) -> 2.4144256e-05 | K6: =IF($Q$1=1, F6, I6) -> 0.19232109 | L6: =B6-C6*SIN(K6) -> -0.00025329339 | M6: =J6+C6*COS(K6) -> 0.00196098 | N6: =B6+C6*SIN(K6) -> 0.00050101832 | O6: =J6-C6*COS(K6) -> -0.0019126915 | P6: =P5-(P5-P5*SQRT(P5/3)-$A$5)/(1-SQRT(3*P5)/2) -> 0.12574351 | R6: =IF($T$1, J6, -0.2) -> -0.2 | V6: 0.64114136 | W6: =$U$2*(COS($U$1)+COS(V6)) -> 0.028296247 | X6: =IF($T$2, $U$2*(SIN($U$1)+SIN(V6)), -0.2) -> -0.2
A7: =A4/100 -> 0.12 | B7: 0.00017836033 | C7: =IF(AND($Q$1=2, $A$3=1), 0, 5*($A$4/100)*(0.2969*SQRT(B7)-0.126*B7-0.3516*(B7^2)+0.2843*(B7^3)-0.1015*(B7^4))) -> 0.0023655976 | D7: =IF($Q$1=1, IF(B7<$A$8, ($A$10/6)*((B7^3)-3*$A$8*(B7^2)+($A$8^2)*(3-$A$8)*B7), (($A$10*($A$8^3))/6)*(1-B7)), " ") -> 3.4751712e-05 | E7: =IF($Q$1=1,IF(B7<$A$8, ($A$10/6)*(3*(B7^2)-6*$A$8*B7+($A$8^2)*(3-$A$8)), -($A$10*($A$8^3))/6), " ") -> 0.19455187 | F7: =IF($Q$1=1, ATAN(E7), " ") -> 0.19215153 | G7: =IF($Q$1=2, IF(A9<>1, IF(B7<$A$11, ($A$12/6)*((B7-$A$11)^3-$A$13*((1-$A$11)^3)*B7-($A$11^3)*B7+$A$11^3), ($A$12/6)*($A$13*(B7-$A$11)^3-$A$13*((1-$A$11)^3)*B7-($A$11^3)*B7+$A$11^3)), 0), " ") | H7: =IF($Q$1=2, IF(A9<>1, IF(B7<$A$11, ($A$12/6)*(3*(B7-$A$11)^2-$A$13*((1-$A$11)^3)-($A$11^3)), ($A$12/6)*(3*$A$13*(B7-$A$11)^2-$A$13*((1-$A$11)^3)-($A$11^3))),0 ), " ") | I7: =IF($Q$1=2, IF(A9<>1, ATAN(H7), 0), " ") | J7: =IF($Q$1=1, D7, G7) -> 3.4751712e-05 | K7: =IF($Q$1=1, F7, I7) -> 0.19215153 | L7: =B7-C7*SIN(K7) -> -0.00027340084 | M7: =J7+C7*COS(K7) -> 0.002356812 | N7: =B7+C7*SIN(K7) -> 0.0006301215 | O7: =J7-C7*COS(K7) -> -0.0022873086 | P7: =P6-(P6-P6*SQRT(P6/3)-$A$5)/(1-SQRT(3*P6)/2) -> 0.12574351 | R7: =IF($T$1, J7, -0.2) -> -0.2 | V7: 0.76936963 | W7: =$U$2*(COS($U$1)+COS(V7)) -> 0.026978272 | X7: =IF($T$2, $U$2*(SIN($U$1)+SIN(V7)), -0.2) -> -0.2
A8: =IF(Q1=1, IF(A3=1, 0.058, IF(A3=2, 0.126, IF(A3=3, 0.2025, IF(A3=4, 0.29, 0.391)))), 0) -> 0.126 | B8: 0.00024276562 | C8: =IF(AND($Q$1=2, $A$3=1), 0, 5*($A$4/100)*(0.2969*SQRT(B8)-0.126*B8-0.3516*(B8^2)+0.2843*(B8^3)-0.1015*(B8^4))) -> 0.0027572227 | D8: =IF($Q$1=1, IF(B8<$A$8, ($A$10/6)*((B8^3)-3*$A$8*(B8^2)+($A$8^2)*(3-$A$8)*B8), (($A$10*($A$8^3))/6)*(1-B8)), " ") -> 4.7275186e-05 | E8: =IF($Q$1=1,IF(B8<$A$8, ($A$10/6)*(3*(B8^2)-6*$A$8*B8+($A$8^2)*(3-$A$8)), -($A$10*($A$8^3))/6), " ") -> 0.19434399 | F8: =IF($Q$1=1, ATAN(E8), " ") -> 0.19195122 | G8: =IF($Q$1=2, IF(A10<>1, IF(B8<$A$11, ($A$12/6)*((B8-$A$11)^3-$A$13*((1-$A$11)^3)*B8-($A$11^3)*B8+$A$11^3), ($A$12/6)*($A$13*(B8-$A$11)^3-$A$13*((1-$A$11)^3)*B8-($A$11^3)*B8+$A$11^3)), 0), " ") | H8: =IF($Q$1=2, IF(A10<>1, IF(B8<$A$11, ($A$12/6)*(3*(B8-$A$11)^2-$A$13*((1-$A$11)^3)-($A$11^3)), ($A$12/6)*(3*$A$13*(B8-$A$11)^2-$A$13*((1-$A$11)^3)-($A$11^3))),0 ), " ") | I8: =IF($Q$1=2, IF(A10<>1, ATAN(H8), 0), " ") | J8: =IF($Q$1=1, D8, G8) -> 4.7275186e-05 | K8: =IF($Q$1=1, F8, I8) -> 0.19195122 | L8: =B8-C8*SIN(K8) -> -0.00028324256 | M8: =J8+C8*COS(K8) -> 0.0027538584 | N8: =B8+C8*SIN(K8) -> 0.00076877379 | O8: =J8-C8*COS(K8) -> -0.002659308 | P8: =P7-(P7-P7*SQRT(P7/3)-$A$5)/(1-SQRT(3*P7)/2) -> 0.12574351 | R8: =IF($T$1, J8, -0.2) -> -0.2 | V8: 0.8975979 | W8: =$U$2*(COS($U$1)+COS(V8)) -> 0.025473142 | X8: =IF($T$2, $U$2*(SIN($U$1)+SIN(V8)), -0.2) -> -0.2
A9: =IF(Q1=1, (3*A8-7*A8^2+8*A8^3-4*A8^4)/SQRT(A8-A8^2)-1.5*(1-2*A8)*(PI()/2-ASIN(1-2*A8)), 0) -> 0.035075129 | B9: 0.00031707769 | C9: =IF(AND($Q$1=2, $A$3=1), 0, 5*($A$4/100)*(0.2969*SQRT(B9)-0.126*B9-0.3516*(B9^2)+0.2843*(B9^3)-0.1015*(B9^4))) -> 0.0031480889 | D9: =IF($Q$1=1, IF(B9<$A$8, ($A$10/6)*((B9^3)-3*$A$8*(B9^2)+($A$8^2)*(3-$A$8)*B9), (($A$10*($A$8^3))/6)*(1-B9)), " ") -> 6.1708384e-05 | E9: =IF($Q$1=1,IF(B9<$A$8, ($A$10/6)*(3*(B9^2)-6*$A$8*B9+($A$8^2)*(3-$A$8)), -($A$10*($A$8^3))/6), " ") -> 0.19410427 | F9: =IF($Q$1=1, ATAN(E9), " ") -> 0.19172021 | G9: =IF($Q$1=2, IF(A11<>1, IF(B9<$A$11, ($A$12/6)*((B9-$A$11)^3-$A$13*((1-$A$11)^3)*B9-($A$11^3)*B9+$A$11^3), ($A$12/6)*($A$13*(B9-$A$11)^3-$A$13*((1-$A$11)^3)*B9-($A$11^3)*B9+$A$11^3)), 0), " ") | H9: =IF($Q$1=2, IF(A11<>1, IF(B9<$A$11, ($A$12/6)*(3*(B9-$A$11)^2-$A$13*((1-$A$11)^3)-($A$11^3)), ($A$12/6)*(3*$A$13*(B9-$A$11)^2-$A$13*((1-$A$11)^3)-($A$11^3))),0 ), " ") | I9: =IF($Q$1=2, IF(A11<>1, ATAN(H9), 0), " ") | J9: =IF($Q$1=1, D9, G9) -> 6.1708384e-05 | K9: =IF($Q$1=1, F9, I9) -> 0.19172021 | L9: =B9-C9*SIN(K9) -> -0.00028278395 | M9: =J9+C9*COS(K9) -> 0.0031521177 | N9: =B9+C9*SIN(K9) -> 0.00091693933 | O9: =J9-C9*COS(K9) -> -0.0030287009 | P9: =P8-(P8-P8*SQRT(P8/3)-$A$5)/(1-SQRT(3*P8)/2) -> 0.12574351 | R9: =IF($T$1, J9, -0.2) -> -0.2 | V9: 1.0258262 | W9: =$U$2*(COS($U$1)+COS(V9)) -> 0.023805572 | X9: =IF($T$2, $U$2*(SIN($U$1)+SIN(V9)), -0.2) -> -0.2
A10: =IF(Q1=1, (6*0.15*A2)/A9, 0) -> 25.659207 | B10: 0.00040129582 | C10: =IF(AND($Q$1=2, $A$3=1), 0, 5*($A$4/100)*(0.2969*SQRT(B10)-0.126*B10-0.3516*(B10^2)+0.2843*(B10^3)-0.1015*(B10^4))) -> 0.0035381943 | D10: =IF($Q$1=1, IF(B10<$A$8, ($A$10/6)*((B10^3)-3*$A$8*(B10^2)+($A$8^2)*(3-$A$8)*B10), (($A$10*($A$8^3))/6)*(1-B10)), " ") -> 7.8044048e-05 | E10: =IF($Q$1=1,IF(B10<$A$8, ($A$10/6)*(3*(B10^2)-6*$A$8*B10+($A$8^2)*(3-$A$8)), -($A$10*($A$8^3))/6), " ") -> 0.19383276 | F10: =IF($Q$1=1, ATAN(E10), " ") -> 0.19145855 | G10: =IF($Q$1=2, IF(A12<>1, IF(B10<$A$11, ($A$12/6)*((B10-$A$11)^3-$A$13*((1-$A$11)^3)*B10-($A$11^3)*B10+$A$11^3), ($A$12/6)*($A$13*(B10-$A$11)^3-$A$13*((1-$A$11)^3)*B10-($A$11^3)*B10+$A$11^3)), 0), " ") | H10: =IF($Q$1=2, IF(A12<>1, IF(B10<$A$11, ($A$12/6)*(3*(B10-$A$11)^2-$A$13*((1-$A$11)^3)-($A$11^3)), ($A$12/6)*(3*$A$13*(B10-$A$11)^2-$A$13*((1-$A$11)^3)-($A$11^3))),0 ), " ") | I10: =IF($Q$1=2, IF(A12<>1, ATAN(H10), 0), " ") | J10: =IF($Q$1=1, D10, G10) -> 7.8044048e-05 | K10: =IF($Q$1=1, F10, I10) -> 0.19145855 | L10: =B10-C10*SIN(K10) -> -0.00027199071 | M10: =J10+C10*COS(K10) -> 0.0035515876 | N10: =B10+C10*SIN(K10) -> 0.0010745824 | O10: =J10-C10*COS(K10) -> -0.0033954995 | P10: =P9-(P9-P9*SQRT(P9/3)-$A$5)/(1-SQRT(3*P9)/2) -> 0.12574351 | R10: =IF($T$1, J10, -0.2) -> -0.2 | V10: 1.1540544 | W10: =$U$2*(COS($U$1)+COS(V10)) -> 0.022002942 | X10: =IF($T$2, $U$2*(SIN($U$1)+SIN(V10)), -0.2) -> -0.2
A11: =IF(Q1=2, IF(A3=2, 0.13, IF(A3=3, 0.217, IF(A3=4, 0.318, IF(A3=5, 0.441, 0)))), 0) -> 0 | B11: 0.00049541917 | C11: =IF(AND($Q$1=2, $A$3=1), 0, 5*($A$4/100)*(0.2969*SQRT(B11)-0.126*B11-0.3516*(B11^2)+0.2843*(B11^3)-0.1015*(B11^4))) -> 0.0039275371 | D11: =IF($Q$1=1, IF(B11<$A$8, ($A$10/6)*((B11^3)-3*$A$8*(B11^2)+($A$8^2)*(3-$A$8)*B11), (($A$10*($A$8^3))/6)*(1-B11)), " ") -> 9.6273964e-05 | E11: =IF($Q$1=1,IF(B11<$A$8, ($A$10/6)*(3*(B11^2)-6*$A$8*B11+($A$8^2)*(3-$A$8)), -($A$10*($A$8^3))/6), " ") -> 0.19352954 | F11: =IF($Q$1=1, ATAN(E11), " ") -> 0.19116629 | G11: =IF($Q$1=2, IF(A13<>1, IF(B11<$A$11, ($A$12/6)*((B11-$A$11)^3-$A$13*((1-$A$11)^3)*B11-($A$11^3)*B11+$A$11^3), ($A$12/6)*($A$13*(B11-$A$11)^3-$A$13*((1-$A$11)^3)*B11-($A$11^3)*B11+$A$11^3)), 0), " ") | H11: =IF($Q$1=2, IF(A13<>1, IF(B11<$A$11, ($A$12/6)*(3*(B11-$A$11)^2-$A$13*((1-$A$11)^3)-($A$11^3)), ($A$12/6)*(3*$A$13*(B11-$A$11)^2-$A$13*((1-$A$11)^3)-($A$11^3))),0 ), " ") | I11: =IF($Q$1=2, IF(A13<>1, ATAN(H11), 0), " ") | J11: =IF($Q$1=1, D11, G11) -> 9.6273964e-05 | K11: =IF($Q$1=1, F11, I11) -> 0.19116629 | L11: =B11-C11*SIN(K11) -> -0.00025082886 | M11: =J11+C11*COS(K11) -> 0.0039522643 | N11: =B11+C11*SIN(K11) -> 0.0012416672 | O11: =J11-C11*COS(K11) -> -0.0037597164 | P11: =P10-(P10-P10*SQRT(P10/3)-$A$5)/(1-SQRT(3*P10)/2) -> 0.12574351 | R11: =IF($T$1, J11, -0.2) -> -0.2 | V11: 1.2822827 | W11: =$U$2*(COS($U$1)+COS(V11)) -> 0.020094853 | X11: =IF($T$2, $U$2*(SIN($U$1)+SIN(V11)), -0.2) -> -0.2
A12: =IF(Q1=2, IF(A3=2, 51.99, IF(A3=3, 15.793, IF(A3=4, 6.52, IF(A3=5, 3.191,0)))), 0) -> 0 | B12: 0.0005994468 | C12: =IF(AND($Q$1=2, $A$3=1), 0, 5*($A$4/100)*(0.2969*SQRT(B12)-0.126*B12-0.3516*(B12^2)+0.2843*(B12^3)-0.1015*(B12^4))) -> 0.004316115 | D12: =IF($Q$1=1, IF(B12<$A$8, ($A$10/6)*((B12^3)-3*$A$8*(B12^2)+($A$8^2)*(3-$A$8)*B12), (($A$10*($A$8^3))/6)*(1-B12)), " ") -> 0.00011638896 | E12: =IF($Q$1=1,IF(B12<$A$8, ($A$10/6)*(3*(B12^2)-6*$A$8*B12+($A$8^2)*(3-$A$8)), -($A$10*($A$8^3))/6), " ") -> 0.19319467 | F12: =IF($Q$1=1, ATAN(E12), " ") -> 0.19084349 | G12: =IF($Q$1=2, IF(A14<>1, IF(B12<$A$11, ($A$12/6)*((B12-$A$11)^3-$A$13*((1-$A$11)^3)*B12-($A$11^3)*B12+$A$11^3), ($A$12/6)*($A$13*(B12-$A$11)^3-$A$13*((1-$A$11)^3)*B12-($A$11^3)*B12+$A$11^3)), 0), " ") | H12: =IF($Q$1=2, IF(A14<>1, IF(B12<$A$11, ($A$12/6)*(3*(B12-$A$11)^2-$A$13*((1-$A$11)^3)-($A$11^3)), ($A$12/6)*(3*$A$13*(B12-$A$11)^2-$A$13*((1-$A$11)^3)-($A$11^3))),0 ), " ") | I12: =IF($Q$1=2, IF(A14<>1, ATAN(H12), 0), " ") | J12: =IF($Q$1=1, D12, G12) -> 0.00011638896 | K12: =IF($Q$1=1, F12, I12) -> 0.19084349 | L12: =B12-C12*SIN(K12) -> -0.00021926473 | M12: =J12+C12*COS(K12) -> 0.0043541431 | N12: =B12+C12*SIN(K12) -> 0.0014181583 | O12: =J12-C12*COS(K12) -> -0.0041213652 | P12: =P11-(P11-P11*SQRT(P11/3)-$A$5)/(1-SQRT(3*P11)/2) -> 0.12574351 | R12: =IF($T$1, J12, -0.2) -> -0.2 | V12: 1.410511 | W12: =$U$2*(COS($U$1)+COS(V12)) -> 0.018112634 | X12: =IF($T$2, $U$2*(SIN($U$1)+SIN(V12)), -0.2) -> -0.2
A13: =IF(Q1=2, IF(A3<>1, IF(A3=2, 0.000764,IF(A3=3, 0.00677,IF(A3=4, 0.0303, 0.1355))), 0), 0) -> 0 | B13: 0.00071337768 | C13: =IF(AND($Q$1=2, $A$3=1), 0, 5*($A$4/100)*(0.2969*SQRT(B13)-0.126*B13-0.3516*(B13^2)+0.2843*(B13^3)-0.1015*(B13^4))) -> 0.0047039259 | D13: =IF($Q$1=1, IF(B13<$A$8, ($A$10/6)*((B13^3)-3*$A$8*(B13^2)+($A$8^2)*(3-$A$8)*B13), (($A$10*($A$8^3))/6)*(1-B13)), " ") -> 0.00013837893 | E13: =IF($Q$1=1,IF(B13<$A$8, ($A$10/6)*(3*(B13^2)-6*$A$8*B13+($A$8^2)*(3-$A$8)), -($A$10*($A$8^3))/6), " ") -> 0.19282825 | F13: =IF($Q$1=1, ATAN(E13), " ") -> 0.19049023 | G13: =IF($Q$1=2, IF(A15<>1, IF(B13<$A$11, ($A$12/6)*((B13-$A$11)^3-$A$13*((1-$A$11)^3)*B13-($A$11^3)*B13+$A$11^3), ($A$12/6)*($A$13*(B13-$A$11)^3-$A$13*((1-$A$11)^3)*B13-($A$11^3)*B13+$A$11^3)), 0), " ") | H13: =IF($Q$1=2, IF(A15<>1, IF(B13<$A$11, ($A$12/6)*(3*(B13-$A$11)^2-$A$13*((1-$A$11)^3)-($A$11^3)), ($A$12/6)*(3*$A$13*(B13-$A$11)^2-$A$13*((1-$A$11)^3)-($A$11^3))),0 ), " ") | I13: =IF($Q$1=2, IF(A15<>1, ATAN(H13), 0), " ") | J13: =IF($Q$1=1, D13, G13) -> 0.00013837893 | K13: =IF($Q$1=1, F13, I13) -> 0.19049023 | L13: =B13-C13*SIN(K13) -> -0.00017726497 | M13: =J13+C13*COS(K13) -> 0.0047572181 | N13: =B13+C13*SIN(K13) -> 0.0016040203 | O13: =J13-C13*COS(K13) -> -0.0044804602 | P13: =P12-(P12-P12*SQRT(P12/3)-$A$5)/(1-SQRT(3*P12)/2) -> 0.12574351 | R13: =IF($T$1, J13, -0.2) -> -0.2 | V13: 1.5387393 | W13: =$U$2*(COS($U$1)+COS(V13)) -> 0.016088833 | X13: =IF($T$2, $U$2*(SIN($U$1)+SIN(V13)), -0.2) -> -0.2
A14: =IF(Q1=2, 0.3, 0.15*A2) -> 0.15 | B14: 0.00083721069 | C14: =IF(AND($Q$1=2, $A$3=1), 0, 5*($A$4/100)*(0.2969*SQRT(B14)-0.126*B14-0.3516*(B14^2)+0.2843*(B14^3)-0.1015*(B14^4))) -> 0.0050909675 | D14: =IF($Q$1=1, IF(B14<$A$8, ($A$10/6)*((B14^3)-3*$A$8*(B14^2)+($A$8^2)*(3-$A$8)*B14), (($A$10*($A$8^3))/6)*(1-B14)), " ") -> 0.00016223279 | E14: =IF($Q$1=1,IF(B14<$A$8, ($A$10/6)*(3*(B14^2)-6*$A$8*B14+($A$8^2)*(3-$A$8)), -($A$10*($A$8^3))/6), " ") -> 0.19243035 | F14: =IF($Q$1=1, ATAN(E14), " ") -> 0.19010657 | G14: =IF($Q$1=2, IF(A16<>1, IF(B14<$A$11, ($A$12/6)*((B14-$A$11)^3-$A$13*((1-$A$11)^3)*B14-($A$11^3)*B14+$A$11^3), ($A$12/6)*($A$13*(B14-$A$11)^3-$A$13*((1-$A$11)^3)*B14-($A$11^3)*B14+$A$11^3)), 0), " ") | H14: =IF($Q$1=2, IF(A16<>1, IF(B14<$A$11, ($A$12/6)*(3*(B14-$A$11)^2-$A$13*((1-$A$11)^3)-($A$11^3)), ($A$12/6)*(3*$A$13*(B14-$A$11)^2-$A$13*((1-$A$11)^3)-($A$11^3))),0 ), " ") | I14: =IF($Q$1=2, IF(A16<>1, ATAN(H14), 0), " ") | J14: =IF($Q$1=1, D14, G14) -> 0.00016223279 | K14: =IF($Q$1=1, F14, I14) -> 0.19010657 | L14: =B14-C14*SIN(K14) -> -0.00012479659 | M14: =J14+C14*COS(K14) -> 0.005161482 | N14: =B14+C14*SIN(K14) -> 0.001799218 | O14: =J14-C14*COS(K14) -> -0.0048370164 | P14: =P13-(P13-P13*SQRT(P13/3)-$A$5)/(1-SQRT(3*P13)/2) -> 0.12574351 | R14: =IF($T$1, J14, -0.2) -> -0.2 | V14: 1.6669675 | W14: =$U$2*(COS($U$1)+COS(V14)) -> 0.014056683 | X14: =IF($T$2, $U$2*(SIN($U$1)+SIN(V14)), -0.2) -> -0.2
B15: 0.00097094459 | C15: =IF(AND($Q$1=2, $A$3=1), 0, 5*($A$4/100)*(0.2969*SQRT(B15)-0.126*B15-0.3516*(B15^2)+0.2843*(B15^3)-0.1015*(B15^4))) -> 0.0054772374 | D15: =IF($Q$1=1, IF(B15<$A$8, ($A$10/6)*((B15^3)-3*$A$8*(B15^2)+($A$8^2)*(3-$A$8)*B15), (($A$10*($A$8^3))/6)*(1-B15)), " ") -> 0.00018793854 | E15: =IF($Q$1=1,IF(B15<$A$8, ($A$10/6)*(3*(B15^2)-6*$A$8*B15+($A$8^2)*(3-$A$8)), -($A$10*($A$8^3))/6), " ") -> 0.19200108 | F15: =IF($Q$1=1, ATAN(E15), " ") -> 0.1896926 | G15: =IF($Q$1=2, IF(A17<>1, IF(B15<$A$11, ($A$12/6)*((B15-$A$11)^3-$A$13*((1-$A$11)^3)*B15-($A$11^3)*B15+$A$11^3), ($A$12/6)*($A$13*(B15-$A$11)^3-$A$13*((1-$A$11)^3)*B15-($A$11^3)*B15+$A$11^3)), 0), " ") | H15: =IF($Q$1=2, IF(A17<>1, IF(B15<$A$11, ($A$12/6)*(3*(B15-$A$11)^2-$A$13*((1-$A$11)^3)-($A$11^3)), ($A$12/6)*(3*$A$13*(B15-$A$11)^2-$A$13*((1-$A$11)^3)-($A$11^3))),0 ), " ") | I15: =IF($Q$1=2, IF(A17<>1, ATAN(H15), 0), " ") | J15: =IF($Q$1=1, D15, G15) -> 0.00018793854 | K15: =IF($Q$1=1, F15, I15) -> 0.1896926 | L15: =B15-C15*SIN(K15) -> -6.1826937e-05 | M15: =J15+C15*COS(K15) -> 0.0055669266 | N15: =B15+C15*SIN(K15) -> 0.0020037161 | O15: =J15-C15*COS(K15) -> -0.0051910495 | P15: =P14-(P14-P14*SQRT(P14/3)-$A$5)/(1-SQRT(3*P14)/2) -> 0.12574351 | R15: =IF($T$1, J15, -0.2) -> -0.2 | V15: 1.7951958 | W15: =$U$2*(COS($U$1)+COS(V15)) -> 0.012049549 | X15: =IF($T$2, $U$2*(SIN($U$1)+SIN(V15)), -0.2) -> -0.2
B16: 0.0011145781 | C16: =IF(AND($Q$1=2, $A$3=1), 0, 5*($A$4/100)*(0.2969*SQRT(B16)-0.126*B16-0.3516*(B16^2)+0.2843*(B16^3)-0.1015*(B16^4))) -> 0.0058627329 | D16: =IF($Q$1=1, IF(B16<$A$8, ($A$10/6)*((B16^3)-3*$A$8*(B16^2)+($A$8^2)*(3-$A$8)*B16), (($A$10*($A$8^3))/6)*(1-B16)), " ") -> 0.00021548324 | E16: =IF($Q$1=1,IF(B16<$A$8, ($A$10/6)*(3*(B16^2)-6*$A$8*B16+($A$8^2)*(3-$A$8)), -($A$10*($A$8^3))/6), " ") -> 0.19154055 | F16: =IF($Q$1=1, ATAN(E16), " ") -> 0.1892484 | G16: =IF($Q$1=2, IF(A18<>1, IF(B16<$A$11, ($A$12/6)*((B16-$A$11)^3-$A$13*((1-$A$11)^3)*B16-($A$11^3)*B16+$A$11^3), ($A$12/6)*($A$13*(B16-$A$11)^3-$A$13*((1-$A$11)^3)*B16-($A$11^3)*B16+$A$11^3)), 0), " ") | H16: =IF($Q$1=2, IF(A18<>1, IF(B16<$A$11, ($A$12/6)*(3*(B16-$A$11)^2-$A$13*((1-$A$11)^3)-($A$11^3)), ($A$12/6)*(3*$A$13*(B16-$A$11)^2-$A$13*((1-$A$11)^3)-($A$11^3))),0 ), " ") | I16: =IF($Q$1=2, IF(A18<>1, ATAN(H16), 0), " ") | J16: =IF($Q$1=1, D16, G16) -> 0.00021548324 | K16: =IF($Q$1=1, F16, I16) -> 0.1892484 | L16: =B16-C16*SIN(K16) -> 1.1676258e-05 | M16: =J16+C16*COS(K16) -> 0.0059735423 | N16: =B16+C16*SIN(K16) -> 0.0022174799 | O16: =J16-C16*COS(K16) -> -0.0055425759 | P16: =P15-(P15-P15*SQRT(P15/3)-$A$5)/(1-SQRT(3*P15)/2) -> 0.12574351 | R16: =IF($T$1, J16, -0.2) -> -0.2 | V16: 1.9234241 | W16: =$U$2*(COS($U$1)+COS(V16)) -> 0.01010039 | X16: =IF($T$2, $U$2*(SIN($U$1)+SIN(V16)), -0.2) -> -0.2
B17: 0.0012681097 | C17: =IF(AND($Q$1=2, $A$3=1), 0, 5*($A$4/100)*(0.2969*SQRT(B17)-0.126*B17-0.3516*(B17^2)+0.2843*(B17^3)-0.1015*(B17^4))) -> 0.0062474514 | D17: =IF($Q$1=1, IF(B17<$A$8, ($A$10/6)*((B17^3)-3*$A$8*(B17^2)+($A$8^2)*(3-$A$8)*B17), (($A$10*($A$8^3))/6)*(1-B17)), " ") -> 0.00024485302 | E17: =IF($Q$1=1,IF(B17<$A$8, ($A$10/6)*(3*(B17^2)-6*$A$8*B17+($A$8^2)*(3-$A$8)), -($A$10*($A$8^3))/6), " ") -> 0.19104887 | F17: =IF($Q$1=1, ATAN(E17), " ") -> 0.18877407 | G17: =IF($Q$1=2, IF(A19<>1, IF(B17<$A$11, ($A$12/6)*((B17-$A$11)^3-$A$13*((1-$A$11)^3)*B17-($A$11^3)*B17+$A$11^3), ($A$12/6)*($A$13*(B17-$A$11)^3-$A$13*((1-$A$11)^3)*B17-($A$11^3)*B17+$A$11^3)), 0), " ") | H17: =IF($Q$1=2, IF(A19<>1, IF(B17<$A$11, ($A$12/6)*(3*(B17-$A$11)^2-$A$13*((1-$A$11)^3)-($A$11^3)), ($A$12/6)*(3*$A$13*(B17-$A$11)^2-$A$13*((1-$A$11)^3)-($A$11^3))),0 ), " ") | I17: =IF($Q$1=2, IF(A19<>1, ATAN(H17), 0), " ") | J17: =IF($Q$1=1, D17, G17) -> 0.00024485302 | K17: =IF($Q$1=1, F17, I17) -> 0.18877407 | L17: =B17-C17*SIN(K17) -> 9.5744892e-05 | M17: =J17+C17*COS(K17) -> 0.0063813186 | N17: =B17+C17*SIN(K17) -> 0.0024404745 | O17: =J17-C17*COS(K17) -> -0.0058916126 | P17: =P16-(P16-P16*SQRT(P16/3)-$A$5)/(1-SQRT(3*P16)/2) -> 0.12574351 | R17: =IF($T$1, J17, -0.2) -> -0.2 | V17: 2.0516523 | W17: =$U$2*(COS($U$1)+COS(V17)) -> 0.0082412108 | X17: =IF($T$2, $U$2*(SIN($U$1)+SIN(V17)), -0.2) -> -0.2
B18: 0.0014315379 | C18: =IF(AND($Q$1=2, $A$3=1), 0, 5*($A$4/100)*(0.2969*SQRT(B18)-0.126*B18-0.3516*(B18^2)+0.2843*(B18^3)-0.1015*(B18^4))) -> 0.0066313902 | D18: =IF($Q$1=1, IF(B18<$A$8, ($A$10/6)*((B18^3)-3*$A$8*(B18^2)+($A$8^2)*(3-$A$8)*B18), (($A$10*($A$8^3))/6)*(1-B18)), " ") -> 0.00027603308 | E18: =IF($Q$1=1,IF(B18<$A$8, ($A$10/6)*(3*(B18^2)-6*$A$8*B18+($A$8^2)*(3-$A$8)), -($A$10*($A$8^3))/6), " ") -> 0.19052615 | F18: =IF($Q$1=1, ATAN(E18), " ") -> 0.18826972 | G18: =IF($Q$1=2, IF(A20<>1, IF(B18<$A$11, ($A$12/6)*((B18-$A$11)^3-$A$13*((1-$A$11)^3)*B18-($A$11^3)*B18+$A$11^3), ($A$12/6)*($A$13*(B18-$A$11)^3-$A$13*((1-$A$11)^3)*B18-($A$11^3)*B18+$A$11^3)), 0), " ") | H18: =IF($Q$1=2, IF(A20<>1, IF(B18<$A$11, ($A$12/6)*(3*(B18-$A$11)^2-$A$13*((1-$A$11)^3)-($A$11^3)), ($A$12/6)*(3*$A$13*(B18-$A$11)^2-$A$13*((1-$A$11)^3)-($A$11^3))),0 ), " ") | I18: =IF($Q$1=2, IF(A20<>1, ATAN(H18), 0), " ") | J18: =IF($Q$1=1, D18, G18) -> 0.00027603308 | K18: =IF($Q$1=1, F18, I18) -> 0.18826972 | L18: =B18-C18*SIN(K18) -> 0.00019041047 | M18: =J18+C18*COS(K18) -> 0.0067902436 | N18: =B18+C18*SIN(K18) -> 0.0026726654 | O18: =J18-C18*COS(K18) -> -0.0062381774 | P18: =P17-(P17-P17*SQRT(P17/3)-$A$5)/(1-SQRT(3*P17)/2) -> 0.12574351 | R18: =IF($T$1, J18, -0.2) -> -0.2 | V18: 2.1798806 | W18: =$U$2*(COS($U$1)+COS(V18)) -> 0.0065025385 | X18: =IF($T$2, $U$2*(SIN($U$1)+SIN(V18)), -0.2) -> -0.2
B19: 0.0016048612 | C19: =IF(AND($Q$1=2, $A$3=1), 0, 5*($A$4/100)*(0.2969*SQRT(B19)-0.126*B19-0.3516*(B19^2)+0.2843*(B19^3)-0.1015*(B19^4))) -> 0.0070145463 | D19: =IF($Q$1=1, IF(B19<$A$8, ($A$10/6)*((B19^3)-3*$A$8*(B19^2)+($A$8^2)*(3-$A$8)*B19), (($A$10*($A$8^3))/6)*(1-B19)), " ") -> 0.00030900771 | E19: =IF($Q$1=1,IF(B19<$A$8, ($A$10/6)*(3*(B19^2)-6*$A$8*B19+($A$8^2)*(3-$A$8)), -($A$10*($A$8^3))/6), " ") -> 0.18997254 | F19: =IF($Q$1=1, ATAN(E19), " ") -> 0.18773544 | G19: =IF($Q$1=2, IF(A21<>1, IF(B19<$A$11, ($A$12/6)*((B19-$A$11)^3-$A$13*((1-$A$11)^3)*B19-($A$11^3)*B19+$A$11^3), ($A$12/6)*($A$13*(B19-$A$11)^3-$A$13*((1-$A$11)^3)*B19-($A$11^3)*B19+$A$11^3)), 0), " ") | H19: =IF($Q$1=2, IF(A21<>1, IF(B19<$A$11, ($A$12/6)*(3*(B19-$A$11)^2-$A$13*((1-$A$11)^3)-($A$11^3)), ($A$12/6)*(3*$A$13*(B19-$A$11)^2-$A$13*((1-$A$11)^3)-($A$11^3))),0 ), " ") | I19: =IF($Q$1=2, IF(A21<>1, ATAN(H19), 0), " ") | J19: =IF($Q$1=1, D19, G19) -> 0.00030900771 | K19: =IF($Q$1=1, F19, I19) -> 0.18773544 | L19: =B19-C19*SIN(K19) -> 0.00029570409 | M19: =J19+C19*COS(K19) -> 0.0072003042 | N19: =B19+C19*SIN(K19) -> 0.0029140183 | O19: =J19-C19*COS(K19) -> -0.0065822888 | P19: =P18-(P18-P18*SQRT(P18/3)-$A$5)/(1-SQRT(3*P18)/2) -> 0.12574351 | R19: =IF($T$1, J19, -0.2) -> -0.2 | V19: 2.3081089 | W19: =$U$2*(COS($U$1)+COS(V19)) -> 0.0049129223 | X19: =IF($T$2, $U$2*(SIN($U$1)+SIN(V19)), -0.2) -> -0.2
B20: 0.0017880778 | C20: =IF(AND($Q$1=2, $A$3=1), 0, 5*($A$4/100)*(0.2969*SQRT(B20)-0.126*B20-0.3516*(B20^2)+0.2843*(B20^3)-0.1015*(B20^4))) -> 0.0073969168 | D20: =IF($Q$1=1, IF(B20<$A$8, ($A$10/6)*((B20^3)-3*$A$8*(B20^2)+($A$8^2)*(3-$A$8)*B20), (($A$10*($A$8^3))/6)*(1-B20)), " ") -> 0.00034376028 | E20: =IF($Q$1=1,IF(B20<$A$8, ($A$10/6)*(3*(B20^2)-6*$A$8*B20+($A$8^2)*(3-$A$8)), -($A$10*($A$8^3))/6), " ") -> 0.18938817 | F20: =IF($Q$1=1, ATAN(E20), " ") -> 0.18717136 | G20: =IF($Q$1=2, IF(A22<>1, IF(B20<$A$11, ($A$12/6)*((B20-$A$11)^3-$A$13*((1-$A$11)^3)*B20-($A$11^3)*B20+$A$11^3), ($A$12/6)*($A$13*(B20-$A$11)^3-$A$13*((1-$A$11)^3)*B20-($A$11^3)*B20+$A$11^3)), 0), " ") | H20: =IF($Q$1=2, IF(A22<>1, IF(B20<$A$11, ($A$12/6)*(3*(B20-$A$11)^2-$A$13*((1-$A$11)^3)-($A$11^3)), ($A$12/6)*(3*$A$13*(B20-$A$11)^2-$A$13*((1-$A$11)^3)-($A$11^3))),0 ), " ") | I20: =IF($Q$1=2, IF(A22<>1, ATAN(H20), 0), " ") | J20: =IF($Q$1=1, D20, G20) -> 0.00034376028 | K20: =IF($Q$1=1, F20, I20) -> 0.18717136 | L20: =B20-C20*SIN(K20) -> 0.00041165644 | M20: =J20+C20*COS(K20) -> 0.0076114864 | N20: =B20+C20*SIN(K20) -> 0.0031644991 | O20: =J20-C20*COS(K20) -> -0.0069239658 | P20: =P19-(P19-P19*SQRT(P19/3)-$A$5)/(1-SQRT(3*P19)/2) -> 0.12574351 | R20: =IF($T$1, J20, -0.2) -> -0.2 | V20: 2.4363372 | W20: =$U$2*(COS($U$1)+COS(V20)) -> 0.0034984638 | X20: =IF($T$2, $U$2*(SIN($U$1)+SIN(V20)), -0.2) -> -0.2
B21: 0.0019811858 | C21: =IF(AND($Q$1=2, $A$3=1), 0, 5*($A$4/100)*(0.2969*SQRT(B21)-0.126*B21-0.3516*(B21^2)+0.2843*(B21^3)-0.1015*(B21^4))) -> 0.0077784985 | D21: =IF($Q$1=1, IF(B21<$A$8, ($A$10/6)*((B21^3)-3*$A$8*(B21^2)+($A$8^2)*(3-$A$8)*B21), (($A$10*($A$8^3))/6)*(1-B21)), " ") -> 0.00038027326 | E21: =IF($Q$1=1,IF(B21<$A$8, ($A$10/6)*(3*(B21^2)-6*$A$8*B21+($A$8^2)*(3-$A$8)), -($A$10*($A$8^3))/6), " ") -> 0.18877317 | F21: =IF($Q$1=1, ATAN(E21), " ") -> 0.1865776 | G21: =IF($Q$1=2, IF(A23<>1, IF(B21<$A$11, ($A$12/6)*((B21-$A$11)^3-$A$13*((1-$A$11)^3)*B21-($A$11^3)*B21+$A$11^3), ($A$12/6)*($A$13*(B21-$A$11)^3-$A$13*((1-$A$11)^3)*B21-($A$11^3)*B21+$A$11^3)), 0), " ") | H21: =IF($Q$1=2, IF(A23<>1, IF(B21<$A$11, ($A$12/6)*(3*(B21-$A$11)^2-$A$13*((1-$A$11)^3)-($A$11^3)), ($A$12/6)*(3*$A$13*(B21-$A$11)^2-$A$13*((1-$A$11)^3)-($A$11^3))),0 ), " ") | I21: =IF($Q$1=2, IF(A23<>1, ATAN(H21), 0), " ") | J21: =IF($Q$1=1, D21, G21) -> 0.00038027326 | K21: =IF($Q$1=1, F21, I21) -> 0.1865776 | L21: =B21-C21*SIN(K21) -> 0.00053829777 | M21: =J21+C21*COS(K21) -> 0.0080237746 | N21: =B21+C21*SIN(K21) -> 0.0034240738 | O21: =J21-C21*COS(K21) -> -0.0072632281 | R21: =IF($T$1, J21, -0.2) -> -0.2 | V21: 2.5645654 | W21: =$U$2*(COS($U$1)+COS(V21)) -> 0.0022823882 | X21: =IF($T$2, $U$2*(SIN($U$1)+SIN(V21)), -0.2) -> -0.2
B22: 0.0021841834 | C22: =IF(AND($Q$1=2, $A$3=1), 0, 5*($A$4/100)*(0.2969*SQRT(B22)-0.126*B22-0.3516*(B22^2)+0.2843*(B22^3)-0.1015*(B22^4))) -> 0.0081592881 | D22: =IF($Q$1=1, IF(B22<$A$8, ($A$10/6)*((B22^3)-3*$A$8*(B22^2)+($A$8^2)*(3-$A$8)*B22), (($A$10*($A$8^3))/6)*(1-B22)), " ") -> 0.00041852822 | E22: =IF($Q$1=1,IF(B22<$A$8, ($A$10/6)*(3*(B22^2)-6*$A$8*B22+($A$8^2)*(3-$A$8)), -($A$10*($A$8^3))/6), " ") -> 0.18812772 | F22: =IF($Q$1=1, ATAN(E22), " ") -> 0.18595428 | G22: =IF($Q$1=2, IF(A24<>1, IF(B22<$A$11, ($A$12/6)*((B22-$A$11)^3-$A$13*((1-$A$11)^3)*B22-($A$11^3)*B22+$A$11^3), ($A$12/6)*($A$13*(B22-$A$11)^3-$A$13*((1-$A$11)^3)*B22-($A$11^3)*B22+$A$11^3)), 0), " ") | H22: =IF($Q$1=2, IF(A24<>1, IF(B22<$A$11, ($A$12/6)*(3*(B22-$A$11)^2-$A$13*((1-$A$11)^3)-($A$11^3)), ($A$12/6)*(3*$A$13*(B22-$A$11)^2-$A$13*((1-$A$11)^3)-($A$11^3))),0 ), " ") | I22: =IF($Q$1=2, IF(A24<>1, ATAN(H22), 0), " ") | J22: =IF($Q$1=1, D22, G22) -> 0.00041852822 | K22: =IF($Q$1=1, F22, I22) -> 0.18595428 | L22: =B22-C22*SIN(K22) -> 0.0006756579 | M22: =J22+C22*COS(K22) -> 0.0084371524 | N22: =B22+C22*SIN(K22) -> 0.0036927089 | O22: =J22-C22*COS(K22) -> -0.0076000959 | R22: =IF($T$1, J22, -0.2) -> -0.2 | V22: 2.6927937 | W22: =$U$2*(COS($U$1)+COS(V22)) -> 0.0012846636 | X22: =IF($T$2, $U$2*(SIN($U$1)+SIN(V22)), -0.2) -> -0.2
B23: 0.0023970685 | C23: =IF(AND($Q$1=2, $A$3=1), 0, 5*($A$4/100)*(0.2969*SQRT(B23)-0.126*B23-0.3516*(B23^2)+0.2843*(B23^3)-0.1015*(B23^4))) -> 0.0085392824 | D23: =IF($Q$1=1, IF(B23<$A$8, ($A$10/6)*((B23^3)-3*$A$8*(B23^2)+($A$8^2)*(3-$A$8)*B23), (($A$10*($A$8^3))/6)*(1-B23)), " ") -> 0.00045850587 | E23: =IF($Q$1=1,IF(B23<$A$8, ($A$10/6)*(3*(B23^2)-6*$A$8*B23+($A$8^2)*(3-$A$8)), -($A$10*($A$8^3))/6), " ") -> 0.18745196 | F23: =IF($Q$1=1, ATAN(E23), " ") -> 0.18530154 | G23: =IF($Q$1=2, IF(A25<>1, IF(B23<$A$11, ($A$12/6)*((B23-$A$11)^3-$A$13*((1-$A$11)^3)*B23-($A$11^3)*B23+$A$11^3), ($A$12/6)*($A$13*(B23-$A$11)^3-$A$13*((1-$A$11)^3)*B23-($A$11^3)*B23+$A$11^3)), 0), " ") | H23: =IF($Q$1=2, IF(A25<>1, IF(B23<$A$11, ($A$12/6)*(3*(B23-$A$11)^2-$A$13*((1-$A$11)^3)-($A$11^3)), ($A$12/6)*(3*$A$13*(B23-$A$11)^2-$A$13*((1-$A$11)^3)-($A$11^3))),0 ), " ") | I23: =IF($Q$1=2, IF(A25<>1, ATAN(H23), 0), " ") | J23: =IF($Q$1=1, D23, G23) -> 0.00045850587 | K23: =IF($Q$1=1, F23, I23) -> 0.18530154 | L23: =B23-C23*SIN(K23) -> 0.00082376617 | M23: =J23+C23*COS(K23) -> 0.0088516021 | N23: =B23+C23*SIN(K23) -> 0.0039703709 | O23: =J23-C23*COS(K23) -> -0.0079345903 | R23: =IF($T$1, J23, -0.2) -> -0.2 | V23: 2.821022 | W23: =$U$2*(COS($U$1)+COS(V23)) -> 0.00052167244 | X23: =IF($T$2, $U$2*(SIN($U$1)+SIN(V23)), -0.2) -> -0.2
B24: 0.0026198391 | C24: =IF(AND($Q$1=2, $A$3=1), 0, 5*($A$4/100)*(0.2969*SQRT(B24)-0.126*B24-0.3516*(B24^2)+0.2843*(B24^3)-0.1015*(B24^4))) -> 0.0089184778 | D24: =IF($Q$1=1, IF(B24<$A$8, ($A$10/6)*((B24^3)-3*$A$8*(B24^2)+($A$8^2)*(3-$A$8)*B24), (($A$10*($A$8^3))/6)*(1-B24)), " ") -> 0.000500186 | E24: =IF($Q$1=1,IF(B24<$A$8, ($A$10/6)*(3*(B24^2)-6*$A$8*B24+($A$8^2)*(3-$A$8)), -($A$10*($A$8^3))/6), " ") -> 0.18674607 | F24: =IF($Q$1=1, ATAN(E24), " ") -> 0.18461953 | G24: =IF($Q$1=2, IF(A26<>1, IF(B24<$A$11, ($A$12/6)*((B24-$A$11)^3-$A$13*((1-$A$11)^3)*B24-($A$11^3)*B24+$A$11^3), ($A$12/6)*($A$13*(B24-$A$11)^3-$A$13*((1-$A$11)^3)*B24-($A$11^3)*B24+$A$11^3)), 0), " ") | H24: =IF($Q$1=2, IF(A26<>1, IF(B24<$A$11, ($A$12/6)*(3*(B24-$A$11)^2-$A$13*((1-$A$11)^3)-($A$11^3)), ($A$12/6)*(3*$A$13*(B24-$A$11)^2-$A$13*((1-$A$11)^3)-($A$11^3))),0 ), " ") | I24: =IF($Q$1=2, IF(A26<>1, ATAN(H24), 0), " ") | J24: =IF($Q$1=1, D24, G24) -> 0.000500186 | K24: =IF($Q$1=1, F24, I24) -> 0.18461953 | L24: =B24-C24*SIN(K24) -> 0.00098265148 | M24: =J24+C24*COS(K24) -> 0.0092671047 | N24: =B24+C24*SIN(K24) -> 0.0042570267 | O24: =J24-C24*COS(K24) -> -0.0082667327 | R24: =IF($T$1, J24, -0.2) -> -0.2 | V24: 2.9492502 | W24: =$U$2*(COS($U$1)+COS(V24)) -> 5.9431161e-06 | X24: =IF($T$2, $U$2*(SIN($U$1)+SIN(V24)), -0.2) -> -0.2
B25: 0.0028524929 | C25: =IF(AND($Q$1=2, $A$3=1), 0, 5*($A$4/100)*(0.2969*SQRT(B25)-0.126*B25-0.3516*(B25^2)+0.2843*(B25^3)-0.1015*(B25^4))) -> 0.0092968709 | D25: =IF($Q$1=1, IF(B25<$A$8, ($A$10/6)*((B25^3)-3*$A$8*(B25^2)+($A$8^2)*(3-$A$8)*B25), (($A$10*($A$8^3))/6)*(1-B25)), " ") -> 0.00054354756 | E25: =IF($Q$1=1,IF(B25<$A$8, ($A$10/6)*(3*(B25^2)-6*$A$8*B25+($A$8^2)*(3-$A$8)), -($A$10*($A$8^3))/6), " ") -> 0.18601022 | F25: =IF($Q$1=1, ATAN(E25), " ") -> 0.18390838 | G25: =IF($Q$1=2, IF(A27<>1, IF(B25<$A$11, ($A$12/6)*((B25-$A$11)^3-$A$13*((1-$A$11)^3)*B25-($A$11^3)*B25+$A$11^3), ($A$12/6)*($A$13*(B25-$A$11)^3-$A$13*((1-$A$11)^3)*B25-($A$11^3)*B25+$A$11^3)), 0), " ") | H25: =IF($Q$1=2, IF(A27<>1, IF(B25<$A$11, ($A$12/6)*(3*(B25-$A$11)^2-$A$13*((1-$A$11)^3)-($A$11^3)), ($A$12/6)*(3*$A$13*(B25-$A$11)^2-$A$13*((1-$A$11)^3)-($A$11^3))),0 ), " ") | I25: =IF($Q$1=2, IF(A27<>1, ATAN(H25), 0), " ") | J25: =IF($Q$1=1, D25, G25) -> 0.00054354756 | K25: =IF($Q$1=1, F25, I25) -> 0.18390838 | L25: =B25-C25*SIN(K25) -> 0.0011523422 | M25: =J25+C25*COS(K25) -> 0.0096836404 | N25: =B25+C25*SIN(K25) -> 0.0045526436 | O25: =J25-C25*COS(K25) -> -0.0085965452 | R25: =IF($T$1, J25, -0.2) -> -0.2 | V25: 3.0774785 | W25: =$U$2*(COS($U$1)+COS(V25)) -> -0.00025405614 | X25: =IF($T$2, $U$2*(SIN($U$1)+SIN(V25)), -0.2) -> -0.2
B26: 0.0030950276 | C26: =IF(AND($Q$1=2, $A$3=1), 0, 5*($A$4/100)*(0.2969*SQRT(B26)-0.126*B26-0.3516*(B26^2)+0.2843*(B26^3)-0.1015*(B26^4))) -> 0.0096744579 | D26: =IF($Q$1=1, IF(B26<$A$8, ($A$10/6)*((B26^3)-3*$A$8*(B26^2)+($A$8^2)*(3-$A$8)*B26), (($A$10*($A$8^3))/6)*(1-B26)), " ") -> 0.00058856863 | E26: =IF($Q$1=1,IF(B26<$A$8, ($A$10/6)*(3*(B26^2)-6*$A$8*B26+($A$8^2)*(3-$A$8)), -($A$10*($A$8^3))/6), " ") -> 0.1852446 | F26: =IF($Q$1=1, ATAN(E26), " ") -> 0.18316826 | G26: =IF($Q$1=2, IF(A28<>1, IF(B26<$A$11, ($A$12/6)*((B26-$A$11)^3-$A$13*((1-$A$11)^3)*B26-($A$11^3)*B26+$A$11^3), ($A$12/6)*($A$13*(B26-$A$11)^3-$A$13*((1-$A$11)^3)*B26-($A$11^3)*B26+$A$11^3)), 0), " ") | H26: =IF($Q$1=2, IF(A28<>1, IF(B26<$A$11, ($A$12/6)*(3*(B26-$A$11)^2-$A$13*((1-$A$11)^3)-($A$11^3)), ($A$12/6)*(3*$A$13*(B26-$A$11)^2-$A$13*((1-$A$11)^3)-($A$11^3))),0 ), " ") | I26: =IF($Q$1=2, IF(A28<>1, ATAN(H26), 0), " ") | J26: =IF($Q$1=1, D26, G26) -> 0.00058856863 | K26: =IF($Q$1=1, F26, I26) -> 0.18316826 | L26: =B26-C26*SIN(K26) -> 0.0013328663 | M26: =J26+C26*COS(K26) -> 0.010101188 | N26: =B26+C26*SIN(K26) -> 0.0048571889 | O26: =J26-C26*COS(K26) -> -0.0089240505 | R26: =IF($T$1, J26, -0.2) -> -0.2 | V26: 3.2057068 | W26: =$U$2*(COS($U$1)+COS(V26)) -> -0.00025405614 | X26: =IF($T$2, $U$2*(SIN($U$1)+SIN(V26)), -0.2) -> -0.2
B27: 0.0033474409 | C27: =IF(AND($Q$1=2, $A$3=1), 0, 5*($A$4/100)*(0.2969*SQRT(B27)-0.126*B27-0.3516*(B27^2)+0.2843*(B27^3)-0.1015*(B27^4))) -> 0.010051235 | D27: =IF($Q$1=1, IF(B27<$A$8, ($A$10/6)*((B27^3)-3*$A$8*(B27^2)+($A$8^2)*(3-$A$8)*B27), (($A$10*($A$8^3))/6)*(1-B27)), " ") -> 0.00063522642 | E27: =IF($Q$1=1,IF(B27<$A$8, ($A$10/6)*(3*(B27^2)-6*$A$8*B27+($A$8^2)*(3-$A$8)), -($A$10*($A$8^3))/6), " ") -> 0.18444939 | F27: =IF($Q$1=1, ATAN(E27), " ") -> 0.18239933 | G27: =IF($Q$1=2, IF(A29<>1, IF(B27<$A$11, ($A$12/6)*((B27-$A$11)^3-$A$13*((1-$A$11)^3)*B27-($A$11^3)*B27+$A$11^3), ($A$12/6)*($A$13*(B27-$A$11)^3-$A$13*((1-$A$11)^3)*B27-($A$11^3)*B27+$A$11^3)), 0), " ") | H27: =IF($Q$1=2, IF(A29<>1, IF(B27<$A$11, ($A$12/6)*(3*(B27-$A$11)^2-$A$13*((1-$A$11)^3)-($A$11^3)), ($A$12/6)*(3*$A$13*(B27-$A$11)^2-$A$13*((1-$A$11)^3)-($A$11^3))),0 ), " ") | I27: =IF($Q$1=2, IF(A29<>1, ATAN(H27), 0), " ") | J27: =IF($Q$1=1, D27, G27) -> 0.00063522642 | K27: =IF($Q$1=1, F27, I27) -> 0.18239933 | L27: =B27-C27*SIN(K27) -> 0.0015242512 | M27: =J27+C27*COS(K27) -> 0.010519725 | N27: =B27+C27*SIN(K27) -> 0.0051706306 | O27: =J27-C27*COS(K27) -> -0.0092492717 | R27: =IF($T$1, J27, -0.2) -> -0.2 | V27: 3.3339351 | W27: =$U$2*(COS($U$1)+COS(V27)) -> 5.9431161e-06 | X27: =IF($T$2, $U$2*(SIN($U$1)+SIN(V27)), -0.2) -> -0.2
B28: 0.0036097302 | C28: =IF(AND($Q$1=2, $A$3=1), 0, 5*($A$4/100)*(0.2969*SQRT(B28)-0.126*B28-0.3516*(B28^2)+0.2843*(B28^3)-0.1015*(B28^4))) -> 0.010427198 | D28: =IF($Q$1=1, IF(B28<$A$8, ($A$10/6)*((B28^3)-3*$A$8*(B28^2)+($A$8^2)*(3-$A$8)*B28), (($A$10*($A$8^3))/6)*(1-B28)), " ") -> 0.00068349735 | E28: =IF($Q$1=1,IF(B28<$A$8, ($A$10/6)*(3*(B28^2)-6*$A$8*B28+($A$8^2)*(3-$A$8)), -($A$10*($A$8^3))/6), " ") -> 0.18362481 | F28: =IF($Q$1=1, ATAN(E28), " ") -> 0.18160176 | G28: =IF($Q$1=2, IF(A30<>1, IF(B28<$A$11, ($A$12/6)*((B28-$A$11)^3-$A$13*((1-$A$11)^3)*B28-($A$11^3)*B28+$A$11^3), ($A$12/6)*($A$13*(B28-$A$11)^3-$A$13*((1-$A$11)^3)*B28-($A$11^3)*B28+$A$11^3)), 0), " ") | H28: =IF($Q$1=2, IF(A30<>1, IF(B28<$A$11, ($A$12/6)*(3*(B28-$A$11)^2-$A$13*((1-$A$11)^3)-($A$11^3)), ($A$12/6)*(3*$A$13*(B28-$A$11)^2-$A$13*((1-$A$11)^3)-($A$11^3))),0 ), " ") | I28: =IF($Q$1=2, IF(A30<>1, ATAN(H28), 0), " ") | J28: =IF($Q$1=1, D28, G28) -> 0.00068349735 | K28: =IF($Q$1=1, F28, I28) -> 0.18160176 | L28: =B28-C28*SIN(K28) -> 0.0017265237 | M28: =J28+C28*COS(K28) -> 0.010939227 | N28: =B28+C28*SIN(K28) -> 0.0054929366 | O28: =J28-C28*COS(K28) -> -0.0095722326 | R28: =IF($T$1, J28, -0.2) -> -0.2 | V28: 3.4621633 | W28: =$U$2*(COS($U$1)+COS(V28)) -> 0.00052167244 | X28: =IF($T$2, $U$2*(SIN($U$1)+SIN(V28)), -0.2) -> -0.2
